Workbook
Name __FPMExcelClient_Connection: "_FPM_BPCNW10_[http://10.87.9.254:8000/sap/bpc/]_[AMSA_PLC]_[COSTOS]_[false]_[false]\1"

Sheet MLP
A1: {=_xll.EPMDimensionOverrideRange("000","CECO",CECOS!$B$2:$B$128)} -> Expansión de CECO sobrescrita
A2: =_xll.EPMOlapMemberO("[CEBE].[PARENTH1].[JE-]","","Gr Antofagasta Miner","","000") -> Gr Antofagasta Miner
A4: =_xll.EPMOlapMemberO("[ENTITY].[PARENTH1].[1001]","","1001 - Minera Los Pelambres","","000") -> 1001 - Minera Los Pelambres
H7: =_xll.EPMOlapMemberO("[TIME].[PARENTH1].[2022.TOTAL]","","2022.TOTAL","","000") -> 2022.TOTAL | K7: =_xll.EPMOlapMemberO("[TIME].[PARENTH1].[2023.TOTAL]","","2023.TOTAL","","000") -> 2023.TOTAL | N7: =_xll.EPMOlapMemberO("[TIME].[PARENTH1].[2024.TOTAL]","","2024.TOTAL","","000") -> 2024.TOTAL | Q7: =_xll.EPMOlapMemberO("[TIME].[PARENTH1].[2025.TOTAL]","","2025.TOTAL","","000") -> 2025.TOTAL
B8: CECO Código | C8: CECO | D8: VP | E8: Item Relevante | F8: Nodo 3 | G8: CeCo Padre | H8: =_xll.EPMOlapMemberO("[CATEGORY].[].[REAL]","","Real - Real","","000") -> Real - Real | I8: =_xll.EPMOlapMemberO("[CATEGORY].[].[PLAN]","","Plan - Plan","","000") -> Plan - Plan | J8: =_xll.FPMXLClient.TechnicalCategory.EPMLocalMember("Var","001","000") -> Var | K8: =_xll.EPMOlapMemberO("[CATEGORY].[].[REAL]","","Real - Real","","000") -> Real - Real | L8: =_xll.EPMOlapMemberO("[CATEGORY].[].[PLAN]","","Plan - Plan","","000") -> Plan - Plan | M8: =_xll.FPMXLClient.TechnicalCategory.EPMLocalMember("Var","001","000") -> Var | N8: =_xll.EPMOlapMemberO("[CATEGORY].[].[REAL]","","Real - Real","","000") -> Real - Real | O8: =_xll.EPMOlapMemberO("[CATEGORY].[].[PLAN]","","Plan - Plan","","000") -> Plan - Plan | P8: =_xll.FPMXLClient.TechnicalCategory.EPMLocalMember("Var","001","000") -> Var | Q8: =_xll.EPMOlapMemberO("[CATEGORY].[].[REAL]","","Real - Real","","000") -> Real - Real | R8: =_xll.EPMOlapMemberO("[CATEGORY].[].[PLAN]","","Plan - Plan","","000") -> Plan - Plan | S8: =_xll.FPMXLClient.TechnicalCategory.EPMLocalMember("Var","001","000") -> Var
A9: =_xll.EPMOlapMemberO("[CECO].[PARENTH3].[AMSA1001AD4507]","","AMSA1001AD4507 - Comunidades RCA","","000") -> AMSA1001AD4507 - Comunidades RCA | B9: =IFERROR(SUBSTITUTE(TRIM(LEFT(A9,FIND("-",A9)-1)),"AMSA",""),"") -> 1001AD4507 | C9: =IFERROR(_xlfn.XLOOKUP(B9,'CECOS Corporativos'!$D:$D,'CECOS Corporativos'!$E:$E,""),"") -> Asuntos Públicos | D9: =IFERROR(_xlfn.XLOOKUP(B9,'CECOS Corporativos'!$D:$D,'CECOS Corporativos'!$J:$J,""),"") -> VP Asuntos Corporativos | E9: Comunidades RCA | F9: =IFERROR(TRIM(LEFT(G9,FIND("-",G9)-1)),"") -> N100100551 | G9: N100100551 - Obligaciones Legales | J9: =I9-H9 -> 0 | M9: =L9-K9 -> 0 | P9: =O9-N9 -> 0 | Q9: 0 | S9: =R9-Q9 -> 0
A10: =_xll.EPMOlapMemberO("[CECO].[PARENTH3].[AMSA1001AD4507]","","AMSA1001AD4507 - Comunidades RCA","","000") -> AMSA1001AD4507 - Comunidades RCA | B10: =IFERROR(SUBSTITUTE(TRIM(LEFT(A10,FIND("-",A10)-1)),"AMSA",""),"") -> 1001AD4507 | C10: =IFERROR(_xlfn.XLOOKUP(B10,'CECOS Corporativos'!$D:$D,'CECOS Corporativos'!$E:$E,""),"") -> Asuntos Públicos | D10: =IFERROR(_xlfn.XLOOKUP(B10,'CECOS Corporativos'!$D:$D,'CECOS Corporativos'!$J:$J,""),"") -> VP Asuntos Corporativos | E10: Liquidación Interna | F10: =IFERROR(TRIM(LEFT(G10,FIND("-",G10)-1)),"") -> N100100551 | G10: N100100551 - Obligaciones Legales | H10: -40845.34 | J10: =I10-H10 -> 40845.34 | M10: =L10-K10 -> 0 | P10: =O10-N10 -> 0 | S10: =R10-Q10 -> 0
A11: =_xll.EPMOlapMemberO("[CECO].[PARENTH3].[AMSA1001AD4514]","","AMSA1001AD4514 - Acuerdo Caimanes","","000") -> AMSA1001AD4514 - Acuerdo Caimanes | B11: =IFERROR(SUBSTITUTE(TRIM(LEFT(A11,FIND("-",A11)-1)),"AMSA",""),"") -> 1001AD4514 | C11: =IFERROR(_xlfn.XLOOKUP(B11,'CECOS Corporativos'!$D:$D,'CECOS Corporativos'!$E:$E,""),"") -> Asuntos Públicos | D11: =IFERROR(_xlfn.XLOOKUP(B11,'CECOS Corporativos'!$D:$D,'CECOS Corporativos'!$J:$J,""),"") -> VP Asuntos Corporativos | E11: Asesorías y Consulto | F11: =IFERROR(TRIM(LEFT(G11,FIND("-",G11)-1)),"") -> N100100551 | G11: N100100551 - Obligaciones Legales | J11: =I11-H11 -> 0 | M11: =L11-K11 -> 0 | N11: 12409.04 | P11: =O11-N11 -> -12409.04 | S11: =R11-Q11 -> 0
A12: =_xll.EPMOlapMemberO("[CECO].[PARENTH3].[AMSA1001AD4514]","","AMSA1001AD4514 - Acuerdo Caimanes","","000") -> AMSA1001AD4514 - Acuerdo Caimanes | B12: =IFERROR(SUBSTITUTE(TRIM(LEFT(A12,FIND("-",A12)-1)),"AMSA",""),"") -> 1001AD4514 | C12: =IFERROR(_xlfn.XLOOKUP(B12,'CECOS Corporativos'!$D:$D,'CECOS Corporativos'!$E:$E,""),"") -> Asuntos Públicos | D12: =IFERROR(_xlfn.XLOOKUP(B12,'CECOS Corporativos'!$D:$D,'CECOS Corporativos'!$J:$J,""),"") -> VP Asuntos Corporativos | E12: Servicios | F12: =IFERROR(TRIM(LEFT(G12,FIND("-",G12)-1)),"") -> N100100551 | G12: N100100551 - Obligaciones Legales | H12: 17201.81 | J12: =I12-H12 -> -17201.81 | K12: 4445.57 | M12: =L12-K12 -> -4445.57 | N12: -13.38 | O12: 108247 | P12: =O12-N12 -> 108260.38 | Q12: 0 | R12: 140064.47 | S12: =R12-Q12 -> 140064.47
A13: =_xll.EPMOlapMemberO("[CECO].[PARENTH3].[AMSA1001AD4514]","","AMSA1001AD4514 - Acuerdo Caimanes","","000") -> AMSA1001AD4514 - Acuerdo Caimanes | B13: =IFERROR(SUBSTITUTE(TRIM(LEFT(A13,FIND("-",A13)-1)),"AMSA",""),"") -> 1001AD4514 | C13: =IFERROR(_xlfn.XLOOKUP(B13,'CECOS Corporativos'!$D:$D,'CECOS Corporativos'!$E:$E,""),"") -> Asuntos Públicos | D13: =IFERROR(_xlfn.XLOOKUP(B13,'CECOS Corporativos'!$D:$D,'CECOS Corporativos'!$J:$J,""),"") -> VP Asuntos Corporativos | E13: Gastos de Viajes | F13: =IFERROR(TRIM(LEFT(G13,FIND("-",G13)-1)),"") -> N100100551 | G13: N100100551 - Obligaciones Legales | H13: 0 | J13: =I13-H13 -> 0 | M13: =L13-K13 -> 0 | P13: =O13-N13 -> 0 | S13: =R13-Q13 -> 0
A14: =_xll.EPMOlapMemberO("[CECO].[PARENTH3].[AMSA1001AD4514]","","AMSA1001AD4514 - Acuerdo Caimanes","","000") -> AMSA1001AD4514 - Acuerdo Caimanes | B14: =IFERROR(SUBSTITUTE(TRIM(LEFT(A14,FIND("-",A14)-1)),"AMSA",""),"") -> 1001AD4514 | C14: =IFERROR(_xlfn.XLOOKUP(B14,'CECOS Corporativos'!$D:$D,'CECOS Corporativos'!$E:$E,""),"") -> Asuntos Públicos | D14: =IFERROR(_xlfn.XLOOKUP(B14,'CECOS Corporativos'!$D:$D,'CECOS Corporativos'!$J:$J,""),"") -> VP Asuntos Corporativos | E14: Impuestos / Patentes | F14: =IFERROR(TRIM(LEFT(G14,FIND("-",G14)-1)),"") -> N100100551 | G14: N100100551 - Obligaciones Legales | H14: 11424.43 | J14: =I14-H14 -> -11424.43 | M14: =L14-K14 -> 0 | P14: =O14-N14 -> 0 | S14: =R14-Q14 -> 0
A15: =_xll.EPMOlapMemberO("[CECO].[PARENTH3].[AMSA1001AD4514]","","AMSA1001AD4514 - Acuerdo Caimanes","","000") -> AMSA1001AD4514 - Acuerdo Caimanes | B15: =IFERROR(SUBSTITUTE(TRIM(LEFT(A15,FIND("-",A15)-1)),"AMSA",""),"") -> 1001AD4514 | C15: =IFERROR(_xlfn.XLOOKUP(B15,'CECOS Corporativos'!$D:$D,'CECOS Corporativos'!$E:$E,""),"") -> Asuntos Públicos | D15: =IFERROR(_xlfn.XLOOKUP(B15,'CECOS Corporativos'!$D:$D,'CECOS Corporativos'!$J:$J,""),"") -> VP Asuntos Corporativos | E15: Otros Gastos | F15: =IFERROR(TRIM(LEFT(G15,FIND("-",G15)-1)),"") -> N100100551 | G15: N100100551 - Obligaciones Legales | I15: 7706 | J15: =I15-H15 -> 7706 | L15: 1141 | M15: =L15-K15 -> 1141 | P15: =O15-N15 -> 0 | S15: =R15-Q15 -> 0
A16: =_xll.EPMOlapMemberO("[CECO].[PARENTH3].[AMSA1001AD4514]","","AMSA1001AD4514 - Acuerdo Caimanes","","000") -> AMSA1001AD4514 - Acuerdo Caimanes | B16: =IFERROR(SUBSTITUTE(TRIM(LEFT(A16,FIND("-",A16)-1)),"AMSA",""),"") -> 1001AD4514 | C16: =IFERROR(_xlfn.XLOOKUP(B16,'CECOS Corporativos'!$D:$D,'CECOS Corporativos'!$E:$E,""),"") -> Asuntos Públicos | D16: =IFERROR(_xlfn.XLOOKUP(B16,'CECOS Corporativos'!$D:$D,'CECOS Corporativos'!$J:$J,""),"") -> VP Asuntos Corporativos | E16: Liquidación Interna | F16: =IFERROR(TRIM(LEFT(G16,FIND("-",G16)-1)),"") -> N100100551 | G16: N100100551 - Obligaciones Legales | H16: 8303.01 | J16: =I16-H16 -> -8303.01 | K16: 135549.49 | M16: =L16-K16 -> -135549.49 | N16: 95867.08 | P16: =O16-N16 -> -95867.08 | Q16: 133068.93 | S16: =R16-Q16 -> -133068.93
A17: =_xll.EPMOlapMemberO("[CECO].[PARENTH3].[AMSA1001AD4521]","","AMSA1001AD4521 - Comunic Externa RCA","","000") -> AMSA1001AD4521 - Comunic Externa RCA | B17: =IFERROR(SUBSTITUTE(TRIM(LEFT(A17,FIND("-",A17)-1)),"AMSA",""),"") -> 1001AD4521 | C17: =IFERROR(_xlfn.XLOOKUP(B17,'CECOS Corporativos'!$D:$D,'CECOS Corporativos'!$E:$E,""),"") -> Comunicaciones | D17: =IFERROR(_xlfn.XLOOKUP(B17,'CECOS Corporativos'!$D:$D,'CECOS Corporativos'!$J:$J,""),"") -> VP Asuntos Corporativos | E17: Servicios | F17: =IFERROR(TRIM(LEFT(G17,FIND("-",G17)-1)),"") -> N100100551 | G17: N100100551 - Obligaciones Legales | H17: 1582.48 | I17: 768786 | J17: =I17-H17 -> 767203.52 | L17: 540202 | M17: =L17-K17 -> 540202 | O17: 605859 | P17: =O17-N17 -> 605859 | R17: 769603.31 | S17: =R17-Q17 -> 769603.31
A18: =_xll.EPMOlapMemberO("[CECO].[PARENTH3].[AMSA1001AD4521]","","AMSA1001AD4521 - Comunic Externa RCA","","000") -> AMSA1001AD4521 - Comunic Externa RCA | B18: =IFERROR(SUBSTITUTE(TRIM(LEFT(A18,FIND("-",A18)-1)),"AMSA",""),"") -> 1001AD4521 | C18: =IFERROR(_xlfn.XLOOKUP(B18,'CECOS Corporativos'!$D:$D,'CECOS Corporativos'!$E:$E,""),"") -> Comunicaciones | D18: =IFERROR(_xlfn.XLOOKUP(B18,'CECOS Corporativos'!$D:$D,'CECOS Corporativos'!$J:$J,""),"") -> VP Asuntos Corporativos | E18: Liquidación Interna | F18: =IFERROR(TRIM(LEFT(G18,FIND("-",G18)-1)),"") -> N100100551 | G18: N100100551 - Obligaciones Legales | H18: 729013.91 | J18: =I18-H18 -> -729013.91 | K18: 636123.14 | M18: =L18-K18 -> -636123.14 | N18: 518147.73 | P18: =O18-N18 -> -518147.73 | Q18: 653262.76 | S18: =R18-Q18 -> -653262.76
A19: =_xll.EPMOlapMemberO("[CECO].[PARENTH3].[AMSA1001AD4500]","","AMSA1001AD4500 - Comun.Mitig. y Comp.","","000") -> AMSA1001AD4500 - Comun.Mitig. y Comp. | B19: =IFERROR(SUBSTITUTE(TRIM(LEFT(A19,FIND("-",A19)-1)),"AMSA",""),"") -> 1001AD4500 | C19: =IFERROR(_xlfn.XLOOKUP(B19,'CECOS Corporativos'!$D:$D,'CECOS Corporativos'!$E:$E,""),"") -> Asuntos Públicos | D19: =IFERROR(_xlfn.XLOOKUP(B19,'CECOS Corporativos'!$D:$D,'CECOS Corporativos'!$J:$J,""),"") -> VP Asuntos Corporativos | E19: Asesorías y Consulto | F19: =IFERROR(TRIM(LEFT(G19,FIND("-",G19)-1)),"") -> N100100552 | G19: N100100552 - Mitigación y Compens | H19: 0 | J19: =I19-H19 -> 0 | K19: 3391.41 | M19: =L19-K19 -> -3391.41 | N19: 46722.03 | P19: =O19-N19 -> -46722.03 | Q19: 28623.16 | S19: =R19-Q19 -> -28623.16
A20: =_xll.EPMOlapMemberO("[CECO].[PARENTH3].[AMSA1001AD4500]","","AMSA1001AD4500 - Comun.Mitig. y Comp.","","000") -> AMSA1001AD4500 - Comun.Mitig. y Comp. | B20: =IFERROR(SUBSTITUTE(TRIM(LEFT(A20,FIND("-",A20)-1)),"AMSA",""),"") -> 1001AD4500 | C20: =IFERROR(_xlfn.XLOOKUP(B20,'CECOS Corporativos'!$D:$D,'CECOS Corporativos'!$E:$E,""),"") -> Asuntos Públicos | D20: =IFERROR(_xlfn.XLOOKUP(B20,'CECOS Corporativos'!$D:$D,'CECOS Corporativos'!$J:$J,""),"") -> VP Asuntos Corporativos | E20: Arriendos | F20: =IFERROR(TRIM(LEFT(G20,FIND("-",G20)-1)),"") -> N100100552 | G20: N100100552 - Mitigación y Compens | H20: 0 | J20: =I20-H20 -> 0 | M20: =L20-K20 -> 0 | P20: =O20-N20 -> 0 | S20: =R20-Q20 -> 0
A21: =_xll.EPMOlapMemberO("[CECO].[PARENTH3].[AMSA1001AD4500]","","AMSA1001AD4500 - Comun.Mitig. y Comp.","","000") -> AMSA1001AD4500 - Comun.Mitig. y Comp. | B21: =IFERROR(SUBSTITUTE(TRIM(LEFT(A21,FIND("-",A21)-1)),"AMSA",""),"") -> 1001AD4500 | C21: =IFERROR(_xlfn.XLOOKUP(B21,'CECOS Corporativos'!$D:$D,'CECOS Corporativos'!$E:$E,""),"") -> Asuntos Públicos | D21: =IFERROR(_xlfn.XLOOKUP(B21,'CECOS Corporativos'!$D:$D,'CECOS Corporativos'!$J:$J,""),"") -> VP Asuntos Corporativos | E21: Servicios | F21: =IFERROR(TRIM(LEFT(G21,FIND("-",G21)-1)),"") -> N100100552 | G21: N100100552 - Mitigación y Compens | H21: 676240.12 | J21: =I21-H21 -> -676240.12 | K21: 350817.41 | M21: =L21-K21 -> -350817.41 | N21: 113225.05 | P21: =O21-N21 -> -113225.05 | Q21: 30566.79 | S21: =R21-Q21 -> -30566.79
A22: =_xll.EPMOlapMemberO("[CECO].[PARENTH3].[AMSA1001AD4500]","","AMSA1001AD4500 - Comun.Mitig. y Comp.","","000") -> AMSA1001AD4500 - Comun.Mitig. y Comp. | B22: =IFERROR(SUBSTITUTE(TRIM(LEFT(A22,FIND("-",A22)-1)),"AMSA",""),"") -> 1001AD4500 | C22: =IFERROR(_xlfn.XLOOKUP(B22,'CECOS Corporativos'!$D:$D,'CECOS Corporativos'!$E:$E,""),"") -> Asuntos Públicos | D22: =IFERROR(_xlfn.XLOOKUP(B22,'CECOS Corporativos'!$D:$D,'CECOS Corporativos'!$J:$J,""),"") -> VP Asuntos Corporativos | E22: Informática y Comuni | F22: =IFERROR(TRIM(LEFT(G22,FIND("-",G22)-1)),"") -> N100100552 | G22: N100100552 - Mitigación y Compens | H22: 1829.96 | I22: 1740 | J22: =I22-H22 -> -89.96 | K22: 1625.45 | L22: 1996 | M22: =L22-K22 -> 370.55 | N22: 1896.59 | O22: 1956 | P22: =O22-N22 -> 59.41 | Q22: 2321.69 | R22: 2112 | S22: =R22-Q22 -> -209.69
A23: =_xll.EPMOlapMemberO("[CECO].[PARENTH3].[AMSA1001AD4500]","","AMSA1001AD4500 - Comun.Mitig. y Comp.","","000") -> AMSA1001AD4500 - Comun.Mitig. y Comp. | B23: =IFERROR(SUBSTITUTE(TRIM(LEFT(A23,FIND("-",A23)-1)),"AMSA",""),"") -> 1001AD4500 | C23: =IFERROR(_xlfn.XLOOKUP(B23,'CECOS Corporativos'!$D:$D,'CECOS Corporativos'!$E:$E,""),"") -> Asuntos Públicos | D23: =IFERROR(_xlfn.XLOOKUP(B23,'CECOS Corporativos'!$D:$D,'CECOS Corporativos'!$J:$J,""),"") -> VP Asuntos Corporativos | E23: Gastos de Viajes | F23: =IFERROR(TRIM(LEFT(G23,FIND("-",G23)-1)),"") -> N100100552 | G23: N100100552 - Mitigación y Compens | J23: =I23-H23 -> 0 | M23: =L23-K23 -> 0 | N23: 0 | P23: =O23-N23 -> 0 | S23: =R23-Q23 -> 0
A24: =_xll.EPMOlapMemberO("[CECO].[PARENTH3].[AMSA1001AD4500]","","AMSA1001AD4500 - Comun.Mitig. y Comp.","","000") -> AMSA1001AD4500 - Comun.Mitig. y Comp. | B24: =IFERROR(SUBSTITUTE(TRIM(LEFT(A24,FIND("-",A24)-1)),"AMSA",""),"") -> 1001AD4500 | C24: =IFERROR(_xlfn.XLOOKUP(B24,'CECOS Corporativos'!$D:$D,'CECOS Corporativos'!$E:$E,""),"") -> Asuntos Públicos | D24: =IFERROR(_xlfn.XLOOKUP(B24,'CECOS Corporativos'!$D:$D,'CECOS Corporativos'!$J:$J,""),"") -> VP Asuntos Corporativos | E24: Impuestos / Patentes | F24: =IFERROR(TRIM(LEFT(G24,FIND("-",G24)-1)),"") -> N100100552 | G24: N100100552 - Mitigación y Compens | I24: 16767 | J24: =I24-H24 -> 16767 | M24: =L24-K24 -> 0 | P24: =O24-N24 -> 0 | S24: =R24-Q24 -> 0
A25: =_xll.EPMOlapMemberO("[CECO].[PARENTH3].[AMSA1001AD4500]","","AMSA1001AD4500 - Comun.Mitig. y Comp.","","000") -> AMSA1001AD4500 - Comun.Mitig. y Comp. | B25: =IFERROR(SUBSTITUTE(TRIM(LEFT(A25,FIND("-",A25)-1)),"AMSA",""),"") -> 1001AD4500 | C25: =IFERROR(_xlfn.XLOOKUP(B25,'CECOS Corporativos'!$D:$D,'CECOS Corporativos'!$E:$E,""),"") -> Asuntos Públicos | D25: =IFERROR(_xlfn.XLOOKUP(B25,'CECOS Corporativos'!$D:$D,'CECOS Corporativos'!$J:$J,""),"") -> VP Asuntos Corporativos | E25: Otros Gastos | F25: =IFERROR(TRIM(LEFT(G25,FIND("-",G25)-1)),"") -> N100100552 | G25: N100100552 - Mitigación y Compens | H25: -0.01 | J25: =I25-H25 -> 0.01 | K25: 0 | M25: =L25-K25 -> 0 | P25: =O25-N25 -> 0 | S25: =R25-Q25 -> 0
A26: =_xll.EPMOlapMemberO("[CECO].[PARENTH3].[AMSA1001AD4500]","","AMSA1001AD4500 - Comun.Mitig. y Comp.","","000") -> AMSA1001AD4500 - Comun.Mitig. y Comp. | B26: =IFERROR(SUBSTITUTE(TRIM(LEFT(A26,FIND("-",A26)-1)),"AMSA",""),"") -> 1001AD4500 | C26: =IFERROR(_xlfn.XLOOKUP(B26,'CECOS Corporativos'!$D:$D,'CECOS Corporativos'!$E:$E,""),"") -> Asuntos Públicos | D26: =IFERROR(_xlfn.XLOOKUP(B26,'CECOS Corporativos'!$D:$D,'CECOS Corporativos'!$J:$J,""),"") -> VP Asuntos Corporativos | E26: Liquidación Interna | F26: =IFERROR(TRIM(LEFT(G26,FIND("-",G26)-1)),"") -> N100100552 | G26: N100100552 - Mitigación y Compens | H26: 327516.76 | J26: =I26-H26 -> -327516.76 | K26: 4550.71 | M26: =L26-K26 -> -4550.71 | N26: 21763.79 | P26: =O26-N26 -> -21763.79 | Q26: 51834.24 | S26: =R26-Q26 -> -51834.24
A27: =_xll.EPMOlapMemberO("[CECO].[PARENTH3].[AMSA1001AD4533]","","AMSA1001AD4533 - Acuerdo Camisas","","000") -> AMSA1001AD4533 - Acuerdo Camisas | B27: =IFERROR(SUBSTITUTE(TRIM(LEFT(A27,FIND("-",A27)-1)),"AMSA",""),"") -> 1001AD4533 | C27: =IFERROR(_xlfn.XLOOKUP(B27,'CECOS Corporativos'!$D:$D,'CECOS Corporativos'!$E:$E,""),"") -> Asuntos Públicos | D27: =IFERROR(_xlfn.XLOOKUP(B27,'CECOS Corporativos'!$D:$D,'CECOS Corporativos'!$J:$J,""),"") -> VP Asuntos Corporativos | E27: Liquidación Interna | F27: =IFERROR(TRIM(LEFT(G27,FIND("-",G27)-1)),"") -> N100100552 | G27: N100100552 - Mitigación y Compens | J27: =I27-H27 -> 0 | K27: 9425.4 | M27: =L27-K27 -> -9425.4 | P27: =O27-N27 -> 0 | S27: =R27-Q27 -> 0
A28: =_xll.EPMOlapMemberO("[CECO].[PARENTH3].[AMSA1001AD4534]","","AMSA1001AD4534 - Acuerdo Llimpo","","000") -> AMSA1001AD4534 - Acuerdo Llimpo | B28: =IFERROR(SUBSTITUTE(TRIM(LEFT(A28,FIND("-",A28)-1)),"AMSA",""),"") -> 1001AD4534 | C28: =IFERROR(_xlfn.XLOOKUP(B28,'CECOS Corporativos'!$D:$D,'CECOS Corporativos'!$E:$E,""),"") -> Asuntos Públicos | D28: =IFERROR(_xlfn.XLOOKUP(B28,'CECOS Corporativos'!$D:$D,'CECOS Corporativos'!$J:$J,""),"") -> VP Asuntos Corporativos | E28: Servicios | F28: =IFERROR(TRIM(LEFT(G28,FIND("-",G28)-1)),"") -> N100100552 | G28: N100100552 - Mitigación y Compens | J28: =I28-H28 -> 0 | M28: =L28-K28 -> 0 | N28: 189.3 | P28: =O28-N28 -> -189.3 | R28: 321711.11 | S28: =R28-Q28 -> 321711.11
A29: =_xll.EPMOlapMemberO("[CECO].[PARENTH3].[AMSA1001AD4534]","","AMSA1001AD4534 - Acuerdo Llimpo","","000") -> AMSA1001AD4534 - Acuerdo Llimpo | B29: =IFERROR(SUBSTITUTE(TRIM(LEFT(A29,FIND("-",A29)-1)),"AMSA",""),"") -> 1001AD4534 | C29: =IFERROR(_xlfn.XLOOKUP(B29,'CECOS Corporativos'!$D:$D,'CECOS Corporativos'!$E:$E,""),"") -> Asuntos Públicos | D29: =IFERROR(_xlfn.XLOOKUP(B29,'CECOS Corporativos'!$D:$D,'CECOS Corporativos'!$J:$J,""),"") -> VP Asuntos Corporativos | E29: Liquidación Interna | F29: =IFERROR(TRIM(LEFT(G29,FIND("-",G29)-1)),"") -> N100100552 | G29: N100100552 - Mitigación y Compens | J29: =I29-H29 -> 0 | K29: 100508.48 | M29: =L29-K29 -> -100508.48 | N29: 21912.53 | P29: =O29-N29 -> -21912.53 | Q29: 2170.64 | S29: =R29-Q29 -> -2170.64
A30: =_xll.EPMOlapMemberO("[CECO].[PARENTH3].[AMSA1001AD4511]","","AMSA1001AD4511 - Somos Choapa IS","","000") -> AMSA1001AD4511 - Somos Choapa IS | B30: =IFERROR(SUBSTITUTE(TRIM(LEFT(A30,FIND("-",A30)-1)),"AMSA",""),"") -> 1001AD4511 | C30: =IFERROR(_xlfn.XLOOKUP(B30,'CECOS Corporativos'!$D:$D,'CECOS Corporativos'!$E:$E,""),"") -> Asuntos Públicos | D30: =IFERROR(_xlfn.XLOOKUP(B30,'CECOS Corporativos'!$D:$D,'CECOS Corporativos'!$J:$J,""),"") -> VP Asuntos Corporativos | E30: Servicios | F30: =IFERROR(TRIM(LEFT(G30,FIND("-",G30)-1)),"") -> N100100553 | G30: N100100553 - Inversión Social | H30: 0 | I30: 63953 | J30: =I30-H30 -> 63953 | L30: 45145 | M30: =L30-K30 -> 45145 | N30: 0 | P30: =O30-N30 -> 0 | S30: =R30-Q30 -> 0
A31: =_xll.EPMOlapMemberO("[CECO].[PARENTH3].[AMSA1001AD4511]","","AMSA1001AD4511 - Somos Choapa IS","","000") -> AMSA1001AD4511 - Somos Choapa IS | B31: =IFERROR(SUBSTITUTE(TRIM(LEFT(A31,FIND("-",A31)-1)),"AMSA",""),"") -> 1001AD4511 | C31: =IFERROR(_xlfn.XLOOKUP(B31,'CECOS Corporativos'!$D:$D,'CECOS Corporativos'!$E:$E,""),"") -> Asuntos Públicos | D31: =IFERROR(_xlfn.XLOOKUP(B31,'CECOS Corporativos'!$D:$D,'CECOS Corporativos'!$J:$J,""),"") -> VP Asuntos Corporativos | E31: Liquidación Interna | F31: =IFERROR(TRIM(LEFT(G31,FIND("-",G31)-1)),"") -> N100100553 | G31: N100100553 - Inversión Social | H31: 20445.06 | J31: =I31-H31 -> -20445.06 | K31: -1149.46 | M31: =L31-K31 -> 1149.46 | N31: 0 | P31: =O31-N31 -> 0 | Q31: 17385.71 | S31: =R31-Q31 -> -17385.71
A32: =_xll.EPMOlapMemberO("[CECO].[PARENTH3].[AMSA1001AD4518]","","AMSA1001AD4518 - Comunidades IS","","000") -> AMSA1001AD4518 - Comunidades IS | B32: =IFERROR(SUBSTITUTE(TRIM(LEFT(A32,FIND("-",A32)-1)),"AMSA",""),"") -> 1001AD4518 | C32: =IFERROR(_xlfn.XLOOKUP(B32,'CECOS Corporativos'!$D:$D,'CECOS Corporativos'!$E:$E,""),"") -> Asuntos Públicos | D32: =IFERROR(_xlfn.XLOOKUP(B32,'CECOS Corporativos'!$D:$D,'CECOS Corporativos'!$J:$J,""),"") -> VP Asuntos Corporativos | E32: Servicios | F32: =IFERROR(TRIM(LEFT(G32,FIND("-",G32)-1)),"") -> N100100553 | G32: N100100553 - Inversión Social | I32: 141065 | J32: =I32-H32 -> 141065 | L32: 136813 | M32: =L32-K32 -> 136813 | O32: 240392 | P32: =O32-N32 -> 240392 | S32: =R32-Q32 -> 0
A33: =_xll.EPMOlapMemberO("[CECO].[PARENTH3].[AMSA1001AD4518]","","AMSA1001AD4518 - Comunidades IS","","000") -> AMSA1001AD4518 - Comunidades IS | B33: =IFERROR(SUBSTITUTE(TRIM(LEFT(A33,FIND("-",A33)-1)),"AMSA",""),"") -> 1001AD4518 | C33: =IFERROR(_xlfn.XLOOKUP(B33,'CECOS Corporativos'!$D:$D,'CECOS Corporativos'!$E:$E,""),"") -> Asuntos Públicos | D33: =IFERROR(_xlfn.XLOOKUP(B33,'CECOS Corporativos'!$D:$D,'CECOS Corporativos'!$J:$J,""),"") -> VP Asuntos Corporativos | E33: Liquidación Interna | F33: =IFERROR(TRIM(LEFT(G33,FIND("-",G33)-1)),"") -> N100100553 | G33: N100100553 - Inversión Social | H33: 455677.99 | J33: =I33-H33 -> -455677.99 | K33: 119045.82 | M33: =L33-K33 -> -119045.82 | N33: 367358.45 | P33: =O33-N33 -> -367358.45 | Q33: 256213.4 | S33: =R33-Q33 -> -256213.4
A34: =_xll.EPMOlapMemberO("[CECO].[PARENTH3].[AMSA1001AD4519]","","AMSA1001AD4519 - Empleabilidad IS","","000") -> AMSA1001AD4519 - Empleabilidad IS | B34: =IFERROR(SUBSTITUTE(TRIM(LEFT(A34,FIND("-",A34)-1)),"AMSA",""),"") -> 1001AD4519 | C34: =IFERROR(_xlfn.XLOOKUP(B34,'CECOS Corporativos'!$D:$D,'CECOS Corporativos'!$E:$E,""),"") -> Empleabilidad | D34: =IFERROR(_xlfn.XLOOKUP(B34,'CECOS Corporativos'!$D:$D,'CECOS Corporativos'!$J:$J,""),"") -> VP Asuntos Corporativos | E34: Servicios | F34: =IFERROR(TRIM(LEFT(G34,FIND("-",G34)-1)),"") -> N100100553 | G34: N100100553 - Inversión Social | I34: 192641 | J34: =I34-H34 -> 192641 | L34: 174932 | M34: =L34-K34 -> 174932 | O34: 275985 | P34: =O34-N34 -> 275985 | R34: 268583.64 | S34: =R34-Q34 -> 268583.64
A35: =_xll.EPMOlapMemberO("[CECO].[PARENTH3].[AMSA1001AD4519]","","AMSA1001AD4519 - Empleabilidad IS","","000") -> AMSA1001AD4519 - Empleabilidad IS | B35: =IFERROR(SUBSTITUTE(TRIM(LEFT(A35,FIND("-",A35)-1)),"AMSA",""),"") -> 1001AD4519 | C35: =IFERROR(_xlfn.XLOOKUP(B35,'CECOS Corporativos'!$D:$D,'CECOS Corporativos'!$E:$E,""),"") -> Empleabilidad | D35: =IFERROR(_xlfn.XLOOKUP(B35,'CECOS Corporativos'!$D:$D,'CECOS Corporativos'!$J:$J,""),"") -> VP Asuntos Corporativos | E35: Liquidación Interna | F35: =IFERROR(TRIM(LEFT(G35,FIND("-",G35)-1)),"") -> N100100553 | G35: N100100553 - Inversión Social | J35: =I35-H35 -> 0 | K35: 118047.55 | M35: =L35-K35 -> -118047.55 | N35: 99445.93 | P35: =O35-N35 -> -99445.93 | Q35: 546127.44 | S35: =R35-Q35 -> -546127.44
A36: =_xll.EPMOlapMemberO("[CECO].[PARENTH3].[AMSA1001AD0506]","","AMSA1001AD0506 - VPACS Corporativo","","000") -> AMSA1001AD0506 - VPACS Corporativo | B36: =IFERROR(SUBSTITUTE(TRIM(LEFT(A36,FIND("-",A36)-1)),"AMSA",""),"") -> 1001AD0506 | C36: =IFERROR(_xlfn.XLOOKUP(B36,'CECOS Corporativos'!$D:$D,'CECOS Corporativos'!$E:$E,""),"") -> VPACS Corporativo (HH Corporativo) | D36: =IFERROR(_xlfn.XLOOKUP(B36,'CECOS Corporativos'!$D:$D,'CECOS Corporativos'!$J:$J,""),"") -> VP Asuntos Corporativos | E36: Servicios Corporativ | F36: =IFERROR(TRIM(LEFT(G36,FIND("-",G36)-1)),"") -> N100100554 | G36: N100100554 - Otros programas y Op | J36: =I36-H36 -> 0 | M36: =L36-K36 -> 0 | N36: 5119721 | O36: 5672806 | P36: =O36-N36 -> 553085 | Q36: 4238493 | R36: 4448965.6 | S36: =R36-Q36 -> 210472.56
A37: =_xll.EPMOlapMemberO("[CECO].[PARENTH3].[AMSA1001AD4513]","","AMSA1001AD4513 - Fundación","","000") -> AMSA1001AD4513 - Fundación | B37: =IFERROR(SUBSTITUTE(TRIM(LEFT(A37,FIND("-",A37)-1)),"AMSA",""),"") -> 1001AD4513 | C37: =IFERROR(_xlfn.XLOOKUP(B37,'CECOS Corporativos'!$D:$D,'CECOS Corporativos'!$E:$E,""),"") -> Fundación FMLP | D37: =IFERROR(_xlfn.XLOOKUP(B37,'CECOS Corporativos'!$D:$D,'CECOS Corporativos'!$J:$J,""),"") -> VP Asuntos Corporativos | E37: Informática y Comuni | F37: =IFERROR(TRIM(LEFT(G37,FIND("-",G37)-1)),"") -> N100100554 | G37: N100100554 - Otros programas y Op | H37: 2411.8 | J37: =I37-H37 -> -2411.8 | K37: 3832.4 | M37: =L37-K37 -> -3832.4 | N37: 7977.38 | P37: =O37-N37 -> -7977.38 | Q37: 7281.45 | S37: =R37-Q37 -> -7281.45
A38: =_xll.EPMOlapMemberO("[CECO].[PARENTH3].[AMSA1001AD4517]","","AMSA1001AD4517 - Comunicación Externa","","000") -> AMSA1001AD4517 - Comunicación Externa | B38: =IFERROR(SUBSTITUTE(TRIM(LEFT(A38,FIND("-",A38)-1)),"AMSA",""),"") -> 1001AD4517 | C38: =IFERROR(_xlfn.XLOOKUP(B38,'CECOS Corporativos'!$D:$D,'CECOS Corporativos'!$E:$E,""),"") -> Comunicaciones | D38: =IFERROR(_xlfn.XLOOKUP(B38,'CECOS Corporativos'!$D:$D,'CECOS Corporativos'!$J:$J,""),"") -> VP Asuntos Corporativos | E38: Administración Perso | F38: =IFERROR(TRIM(LEFT(G38,FIND("-",G38)-1)),"") -> N100100554 | G38: N100100554 - Otros programas y Op | H38: 0 | J38: =I38-H38 -> 0 | M38: =L38-K38 -> 0 | P38: =O38-N38 -> 0 | S38: =R38-Q38 -> 0
A39: =_xll.EPMOlapMemberO("[CECO].[PARENTH3].[AMSA1001AD4517]","","AMSA1001AD4517 - Comunicación Externa","","000") -> AMSA1001AD4517 - Comunicación Externa | B39: =IFERROR(SUBSTITUTE(TRIM(LEFT(A39,FIND("-",A39)-1)),"AMSA",""),"") -> 1001AD4517 | C39: =IFERROR(_xlfn.XLOOKUP(B39,'CECOS Corporativos'!$D:$D,'CECOS Corporativos'!$E:$E,""),"") -> Comunicaciones | D39: =IFERROR(_xlfn.XLOOKUP(B39,'CECOS Corporativos'!$D:$D,'CECOS Corporativos'!$J:$J,""),"") -> VP Asuntos Corporativos | E39: Entrenamiento | F39: =IFERROR(TRIM(LEFT(G39,FIND("-",G39)-1)),"") -> N100100554 | G39: N100100554 - Otros programas y Op | J39: =I39-H39 -> 0 | K39: -3510.93 | M39: =L39-K39 -> 3510.93 | P39: =O39-N39 -> 0 | S39: =R39-Q39 -> 0
A40: =_xll.EPMOlapMemberO("[CECO].[PARENTH3].[AMSA1001AD4517]","","AMSA1001AD4517 - Comunicación Externa","","000") -> AMSA1001AD4517 - Comunicación Externa | B40: =IFERROR(SUBSTITUTE(TRIM(LEFT(A40,FIND("-",A40)-1)),"AMSA",""),"") -> 1001AD4517 | C40: =IFERROR(_xlfn.XLOOKUP(B40,'CECOS Corporativos'!$D:$D,'CECOS Corporativos'!$E:$E,""),"") -> Comunicaciones | D40: =IFERROR(_xlfn.XLOOKUP(B40,'CECOS Corporativos'!$D:$D,'CECOS Corporativos'!$J:$J,""),"") -> VP Asuntos Corporativos | E40: Asesorías y Consulto | F40: =IFERROR(TRIM(LEFT(G40,FIND("-",G40)-1)),"") -> N100100554 | G40: N100100554 - Otros programas y Op | H40: 132591.18 | I40: 63667 | J40: =I40-H40 -> -68924.18 | K40: 172369.87 | L40: 23694 | M40: =L40-K40 -> -148675.87 | N40: 0 | O40: 46937 | P40: =O40-N40 -> 46937 | S40: =R40-Q40 -> 0
A41: =_xll.EPMOlapMemberO("[CECO].[PARENTH3].[AMSA1001AD4517]","","AMSA1001AD4517 - Comunicación Externa","","000") -> AMSA1001AD4517 - Comunicación Externa | B41: =IFERROR(SUBSTITUTE(TRIM(LEFT(A41,FIND("-",A41)-1)),"AMSA",""),"") -> 1001AD4517 | C41: =IFERROR(_xlfn.XLOOKUP(B41,'CECOS Corporativos'!$D:$D,'CECOS Corporativos'!$E:$E,""),"") -> Comunicaciones | D41: =IFERROR(_xlfn.XLOOKUP(B41,'CECOS Corporativos'!$D:$D,'CECOS Corporativos'!$J:$J,""),"") -> VP Asuntos Corporativos | E41: Servicios | F41: =IFERROR(TRIM(LEFT(G41,FIND("-",G41)-1)),"") -> N100100554 | G41: N100100554 - Otros programas y Op | H41: 0 | I41: 19181 | J41: =I41-H41 -> 19181 | K41: 107399.96 | M41: =L41-K41 -> -107399.96 | N41: -117465.5 | P41: =O41-N41 -> 117465.5 | S41: =R41-Q41 -> 0
A42: =_xll.EPMOlapMemberO("[CECO].[PARENTH3].[AMSA1001AD4517]","","AMSA1001AD4517 - Comunicación Externa","","000") -> AMSA1001AD4517 - Comunicación Externa | B42: =IFERROR(SUBSTITUTE(TRIM(LEFT(A42,FIND("-",A42)-1)),"AMSA",""),"") -> 1001AD4517 | C42: =IFERROR(_xlfn.XLOOKUP(B42,'CECOS Corporativos'!$D:$D,'CECOS Corporativos'!$E:$E,""),"") -> Comunicaciones | D42: =IFERROR(_xlfn.XLOOKUP(B42,'CECOS Corporativos'!$D:$D,'CECOS Corporativos'!$J:$J,""),"") -> VP Asuntos Corporativos | E42: Informática y Comuni | F42: =IFERROR(TRIM(LEFT(G42,FIND("-",G42)-1)),"") -> N100100554 | G42: N100100554 - Otros programas y Op | H42: 57605.28 | I42: 90100 | J42: =I42-H42 -> 32494.72 | K42: -10.25 | L42: 304314 | M42: =L42-K42 -> 304324.25 | O42: 655497 | P42: =O42-N42 -> 655497 | Q42: 14.79 | R42: 232088.88 | S42: =R42-Q42 -> 232074.09
A43: =_xll.EPMOlapMemberO("[CECO].[PARENTH3].[AMSA1001AD4517]","","AMSA1001AD4517 - Comunicación Externa","","000") -> AMSA1001AD4517 - Comunicación Externa | B43: =IFERROR(SUBSTITUTE(TRIM(LEFT(A43,FIND("-",A43)-1)),"AMSA",""),"") -> 1001AD4517 | C43: =IFERROR(_xlfn.XLOOKUP(B43,'CECOS Corporativos'!$D:$D,'CECOS Corporativos'!$E:$E,""),"") -> Comunicaciones | D43: =IFERROR(_xlfn.XLOOKUP(B43,'CECOS Corporativos'!$D:$D,'CECOS Corporativos'!$J:$J,""),"") -> VP Asuntos Corporativos | E43: Gastos de Viajes | F43: =IFERROR(TRIM(LEFT(G43,FIND("-",G43)-1)),"") -> N100100554 | G43: N100100554 - Otros programas y Op | J43: =I43-H43 -> 0 | K43: -11500.64 | M43: =L43-K43 -> 11500.64 | P43: =O43-N43 -> 0 | S43: =R43-Q43 -> 0
...

Sheet ANT
A1: {=_xll.EPMDimensionOverrideRange("000","CECO",CECOS!$B$2:$B$128)} -> Expansión de CECO sobrescrita
A2: =_xll.EPMOlapMemberO("[CEBE].[PARENTH1].[JE-]","","Gr Antofagasta Miner","","000") -> Gr Antofagasta Miner
A4: =_xll.EPMOlapMemberO("[ENTITY].[PARENTH1].[1003]","","1003 - Minera Antucoya","","000") -> 1003 - Minera Antucoya
I7: =_xll.EPMOlapMemberO("[TIME].[PARENTH1].[2022.TOTAL]","","2022.TOTAL","","000") -> 2022.TOTAL | L7: =_xll.EPMOlapMemberO("[TIME].[PARENTH1].[2023.TOTAL]","","2023.TOTAL","","000") -> 2023.TOTAL | O7: =_xll.EPMOlapMemberO("[TIME].[PARENTH1].[2024.TOTAL]","","2024.TOTAL","","000") -> 2024.TOTAL | R7: =_xll.EPMOlapMemberO("[TIME].[PARENTH1].[2025.TOTAL]","","2025.TOTAL","","000") -> 2025.TOTAL
B8: CECO Código | C8: CECO | D8: VP | E8: Item Relevante | F8: Nodo 3 | G8: CeCo Padre | H8: =_xll.EPMOlapMemberO("[CATEGORY].[].[REAL]","","Real - Real","","000") -> #NAME? | I8: =_xll.EPMOlapMemberO("[CATEGORY].[].[PLAN]","","Plan - Plan","","000") -> #NAME? | J8: =_xll.FPMXLClient.TechnicalCategory.EPMLocalMember("Var","001","000") -> Var | K8: =_xll.EPMOlapMemberO("[CATEGORY].[].[REAL]","","Real - Real","","000") -> #NAME? | L8: =_xll.EPMOlapMemberO("[CATEGORY].[].[PLAN]","","Plan - Plan","","000") -> #NAME? | M8: =_xll.FPMXLClient.TechnicalCategory.EPMLocalMember("Var","001","000") -> Var | N8: =_xll.EPMOlapMemberO("[CATEGORY].[].[REAL]","","Real - Real","","000") -> #NAME? | O8: =_xll.EPMOlapMemberO("[CATEGORY].[].[PLAN]","","Plan - Plan","","000") -> #NAME? | P8: =_xll.FPMXLClient.TechnicalCategory.EPMLocalMember("Var","001","000") -> Var | Q8: =_xll.EPMOlapMemberO("[CATEGORY].[].[REAL]","","Real - Real","","000") -> #NAME? | R8: =_xll.EPMOlapMemberO("[CATEGORY].[].[PLAN]","","Plan - Plan","","000") -> #NAME? | S8: =_xll.FPMXLClient.TechnicalCategory.EPMLocalMember("Var","001","000") -> Var
A9: =_xll.EPMOlapMemberO("[CECO].[PARENTH3].[AMSA1003AD0507]","","AMSA1003AD0507 - VPACS Corporativo","","000") -> AMSA1003AD0507 - VPACS Corporativo | B9: =IFERROR(SUBSTITUTE(TRIM(LEFT(A9,FIND("-",A9)-1)),"AMSA",""),"") -> 1003AD0507 | C9: =IFERROR(_xlfn.XLOOKUP(B9,'CECOS Corporativos'!$D:$D,'CECOS Corporativos'!$E:$E,""),"") -> VPACS Corporativo (HH Corporativo) | D9: =IFERROR(_xlfn.XLOOKUP(B9,'CECOS Corporativos'!$D:$D,'CECOS Corporativos'!$J:$J,""),"") -> VP Asuntos Corporativos | E9: =_xll.EPMOlapMemberO("[CLACO].[PARENTH7].[AMSASERV_CORP]","","Servicios Corporativ","","000") -> Servicios Corporativ | F9: =IFERROR(TRIM(LEFT(G9,FIND("-",G9)-1)),"") -> N100300500 | G9: N100300500 - Antucoya No Operacio | H9: =IFERROR(_xlfn.XLOOKUP(F9,'CECOS Corporativos'!$K:$K,'CECOS Corporativos'!$D:$D,""),"") -> 1003AD4505 | K9: =J9-I9 -> 0 | N9: =M9-L9 -> 0 | O9: 1044408 | P9: 1157235 | Q9: =P9-O9 -> 112827 | R9: 961205 | S9: 1008932.3 | T9: =S9-R9 -> 47727.31
A10: =_xll.EPMOlapMemberO("[CECO].[PARENTH3].[AMSA1003AD4505]","","AMSA1003AD4505 - Asunt Publ y Comunid","","000") -> AMSA1003AD4505 - Asunt Publ y Comunid | B10: =IFERROR(SUBSTITUTE(TRIM(LEFT(A10,FIND("-",A10)-1)),"AMSA",""),"") -> 1003AD4505 | C10: =IFERROR(_xlfn.XLOOKUP(B10,'CECOS Corporativos'!$D:$D,'CECOS Corporativos'!$E:$E,""),"") -> Asuntos Públicos y Comunidades | D10: =IFERROR(_xlfn.XLOOKUP(B10,'CECOS Corporativos'!$D:$D,'CECOS Corporativos'!$J:$J,""),"") -> VP Asuntos Corporativos | E10: =_xll.EPMOlapMemberO("[CLACO].[PARENTH7].[AMSAMAT_Y_REP.2]","","Materiales y repuest","","000") -> Materiales y repuest | F10: =IFERROR(TRIM(LEFT(G10,FIND("-",G10)-1)),"") -> N100300500 | G10: N100300500 - Antucoya No Operacio | H10: =IFERROR(_xlfn.XLOOKUP(F10,'CECOS Corporativos'!$K:$K,'CECOS Corporativos'!$D:$D,""),"") -> 1003AD4505 | I10: 602.29 | K10: =J10-I10 -> -602.29 | N10: =M10-L10 -> 0 | Q10: =P10-O10 -> 0 | T10: =S10-R10 -> 0
A11: =_xll.EPMOlapMemberO("[CECO].[PARENTH3].[AMSA1003AD4505]","","AMSA1003AD4505 - Asunt Publ y Comunid","","000") -> AMSA1003AD4505 - Asunt Publ y Comunid | B11: =IFERROR(SUBSTITUTE(TRIM(LEFT(A11,FIND("-",A11)-1)),"AMSA",""),"") -> 1003AD4505 | C11: =IFERROR(_xlfn.XLOOKUP(B11,'CECOS Corporativos'!$D:$D,'CECOS Corporativos'!$E:$E,""),"") -> Asuntos Públicos y Comunidades | D11: =IFERROR(_xlfn.XLOOKUP(B11,'CECOS Corporativos'!$D:$D,'CECOS Corporativos'!$J:$J,""),"") -> VP Asuntos Corporativos | E11: =_xll.EPMOlapMemberO("[CLACO].[PARENTH7].[AMSAADM_PERSON]","","Administración Perso","","000") -> Administración Perso | F11: =IFERROR(TRIM(LEFT(G11,FIND("-",G11)-1)),"") -> N100300500 | G11: N100300500 - Antucoya No Operacio | H11: =IFERROR(_xlfn.XLOOKUP(F11,'CECOS Corporativos'!$K:$K,'CECOS Corporativos'!$D:$D,""),"") -> 1003AD4505 | I11: -1427.15 | K11: =J11-I11 -> 1427.15 | N11: =M11-L11 -> 0 | Q11: =P11-O11 -> 0 | T11: =S11-R11 -> 0
A12: =_xll.EPMOlapMemberO("[CECO].[PARENTH3].[AMSA1003AD4505]","","AMSA1003AD4505 - Asunt Publ y Comunid","","000") -> AMSA1003AD4505 - Asunt Publ y Comunid | B12: =IFERROR(SUBSTITUTE(TRIM(LEFT(A12,FIND("-",A12)-1)),"AMSA",""),"") -> 1003AD4505 | C12: =IFERROR(_xlfn.XLOOKUP(B12,'CECOS Corporativos'!$D:$D,'CECOS Corporativos'!$E:$E,""),"") -> Asuntos Públicos y Comunidades | D12: =IFERROR(_xlfn.XLOOKUP(B12,'CECOS Corporativos'!$D:$D,'CECOS Corporativos'!$J:$J,""),"") -> VP Asuntos Corporativos | E12: =_xll.EPMOlapMemberO("[CLACO].[PARENTH7].[AMSAENTRENAMI]","","Entrenamiento","","000") -> Entrenamiento | F12: =IFERROR(TRIM(LEFT(G12,FIND("-",G12)-1)),"") -> N100300500 | G12: N100300500 - Antucoya No Operacio | H12: =IFERROR(_xlfn.XLOOKUP(F12,'CECOS Corporativos'!$K:$K,'CECOS Corporativos'!$D:$D,""),"") -> 1003AD4505 | K12: =J12-I12 -> 0 | N12: =M12-L12 -> 0 | Q12: =P12-O12 -> 0 | R12: 1350.37 | T12: =S12-R12 -> -1350.37
A13: =_xll.EPMOlapMemberO("[CECO].[PARENTH3].[AMSA1003AD4505]","","AMSA1003AD4505 - Asunt Publ y Comunid","","000") -> AMSA1003AD4505 - Asunt Publ y Comunid | B13: =IFERROR(SUBSTITUTE(TRIM(LEFT(A13,FIND("-",A13)-1)),"AMSA",""),"") -> 1003AD4505 | C13: =IFERROR(_xlfn.XLOOKUP(B13,'CECOS Corporativos'!$D:$D,'CECOS Corporativos'!$E:$E,""),"") -> Asuntos Públicos y Comunidades | D13: =IFERROR(_xlfn.XLOOKUP(B13,'CECOS Corporativos'!$D:$D,'CECOS Corporativos'!$J:$J,""),"") -> VP Asuntos Corporativos | E13: =_xll.EPMOlapMemberO("[CLACO].[PARENTH7].[AMSAASESORIAS]","","Asesorías y Consulto","","000") -> Asesorías y Consulto | F13: =IFERROR(TRIM(LEFT(G13,FIND("-",G13)-1)),"") -> N100300500 | G13: N100300500 - Antucoya No Operacio | H13: =IFERROR(_xlfn.XLOOKUP(F13,'CECOS Corporativos'!$K:$K,'CECOS Corporativos'!$D:$D,""),"") -> 1003AD4505 | I13: 120720.09 | J13: 74702 | K13: =J13-I13 -> -46018.09 | L13: 125189.99 | M13: 17279 | N13: =M13-L13 -> -107910.99 | O13: 21760.51 | Q13: =P13-O13 -> -21760.51 | R13: 29750.19 | S13: 10433.84 | T13: =S13-R13 -> -19316.35
A14: =_xll.EPMOlapMemberO("[CECO].[PARENTH3].[AMSA1003AD4505]","","AMSA1003AD4505 - Asunt Publ y Comunid","","000") -> AMSA1003AD4505 - Asunt Publ y Comunid | B14: =IFERROR(SUBSTITUTE(TRIM(LEFT(A14,FIND("-",A14)-1)),"AMSA",""),"") -> 1003AD4505 | C14: =IFERROR(_xlfn.XLOOKUP(B14,'CECOS Corporativos'!$D:$D,'CECOS Corporativos'!$E:$E,""),"") -> Asuntos Públicos y Comunidades | D14: =IFERROR(_xlfn.XLOOKUP(B14,'CECOS Corporativos'!$D:$D,'CECOS Corporativos'!$J:$J,""),"") -> VP Asuntos Corporativos | E14: =_xll.EPMOlapMemberO("[CLACO].[PARENTH7].[AMSASERVICIOS]","","Servicios","","000") -> Servicios | F14: =IFERROR(TRIM(LEFT(G14,FIND("-",G14)-1)),"") -> N100300500 | G14: N100300500 - Antucoya No Operacio | H14: =IFERROR(_xlfn.XLOOKUP(F14,'CECOS Corporativos'!$K:$K,'CECOS Corporativos'!$D:$D,""),"") -> 1003AD4505 | I14: 259648.63 | J14: 432257 | K14: =J14-I14 -> 172608.37 | L14: 203961.93 | N14: =M14-L14 -> -203961.93 | O14: 174781.97 | P14: 47518 | Q14: =P14-O14 -> -127263.97 | R14: 95903.09 | S14: 45206.35 | T14: =S14-R14 -> -50696.74
A15: =_xll.EPMOlapMemberO("[CECO].[PARENTH3].[AMSA1003AD4505]","","AMSA1003AD4505 - Asunt Publ y Comunid","","000") -> AMSA1003AD4505 - Asunt Publ y Comunid | B15: =IFERROR(SUBSTITUTE(TRIM(LEFT(A15,FIND("-",A15)-1)),"AMSA",""),"") -> 1003AD4505 | C15: =IFERROR(_xlfn.XLOOKUP(B15,'CECOS Corporativos'!$D:$D,'CECOS Corporativos'!$E:$E,""),"") -> Asuntos Públicos y Comunidades | D15: =IFERROR(_xlfn.XLOOKUP(B15,'CECOS Corporativos'!$D:$D,'CECOS Corporativos'!$J:$J,""),"") -> VP Asuntos Corporativos | E15: =_xll.EPMOlapMemberO("[CLACO].[PARENTH7].[AMSAINFORMATIC]","","Informática y Comuni","","000") -> Informática y Comuni | F15: =IFERROR(TRIM(LEFT(G15,FIND("-",G15)-1)),"") -> N100300500 | G15: N100300500 - Antucoya No Operacio | H15: =IFERROR(_xlfn.XLOOKUP(F15,'CECOS Corporativos'!$K:$K,'CECOS Corporativos'!$D:$D,""),"") -> 1003AD4505 | I15: 167.37 | K15: =J15-I15 -> -167.37 | L15: 0 | N15: =M15-L15 -> 0 | Q15: =P15-O15 -> 0 | T15: =S15-R15 -> 0
A16: =_xll.EPMOlapMemberO("[CECO].[PARENTH3].[AMSA1003AD4505]","","AMSA1003AD4505 - Asunt Publ y Comunid","","000") -> AMSA1003AD4505 - Asunt Publ y Comunid | B16: =IFERROR(SUBSTITUTE(TRIM(LEFT(A16,FIND("-",A16)-1)),"AMSA",""),"") -> 1003AD4505 | C16: =IFERROR(_xlfn.XLOOKUP(B16,'CECOS Corporativos'!$D:$D,'CECOS Corporativos'!$E:$E,""),"") -> Asuntos Públicos y Comunidades | D16: =IFERROR(_xlfn.XLOOKUP(B16,'CECOS Corporativos'!$D:$D,'CECOS Corporativos'!$J:$J,""),"") -> VP Asuntos Corporativos | E16: =_xll.EPMOlapMemberO("[CLACO].[PARENTH7].[AMSAG_VIAJES]","","Gastos de Viajes","","000") -> Gastos de Viajes | F16: =IFERROR(TRIM(LEFT(G16,FIND("-",G16)-1)),"") -> N100300500 | G16: N100300500 - Antucoya No Operacio | H16: =IFERROR(_xlfn.XLOOKUP(F16,'CECOS Corporativos'!$K:$K,'CECOS Corporativos'!$D:$D,""),"") -> 1003AD4505 | I16: 113522.3 | J16: 11481.47 | K16: =J16-I16 -> -102040.83 | L16: 2254.49 | N16: =M16-L16 -> -2254.49 | O16: 1815.48 | Q16: =P16-O16 -> -1815.48 | R16: 740.54 | T16: =S16-R16 -> -740.54
A17: =_xll.EPMOlapMemberO("[CECO].[PARENTH3].[AMSA1003AD4505]","","AMSA1003AD4505 - Asunt Publ y Comunid","","000") -> AMSA1003AD4505 - Asunt Publ y Comunid | B17: =IFERROR(SUBSTITUTE(TRIM(LEFT(A17,FIND("-",A17)-1)),"AMSA",""),"") -> 1003AD4505 | C17: =IFERROR(_xlfn.XLOOKUP(B17,'CECOS Corporativos'!$D:$D,'CECOS Corporativos'!$E:$E,""),"") -> Asuntos Públicos y Comunidades | D17: =IFERROR(_xlfn.XLOOKUP(B17,'CECOS Corporativos'!$D:$D,'CECOS Corporativos'!$J:$J,""),"") -> VP Asuntos Corporativos | E17: =_xll.EPMOlapMemberO("[CLACO].[PARENTH7].[AMSAGGENERALES.2]","","Otros Gastos","","000") -> Otros Gastos | F17: =IFERROR(TRIM(LEFT(G17,FIND("-",G17)-1)),"") -> N100300500 | G17: N100300500 - Antucoya No Operacio | H17: =IFERROR(_xlfn.XLOOKUP(F17,'CECOS Corporativos'!$K:$K,'CECOS Corporativos'!$D:$D,""),"") -> 1003AD4505 | I17: 86772 | J17: 53254 | K17: =J17-I17 -> -33518 | L17: 81508.05 | M17: 22767 | N17: =M17-L17 -> -58741.05 | O17: 9308.79 | P17: 8443 | Q17: =P17-O17 -> -865.79 | R17: 30489.02 | S17: 24861.15 | T17: =S17-R17 -> -5627.87
A18: =_xll.EPMOlapMemberO("[CECO].[PARENTH3].[AMSA1003AD4505]","","AMSA1003AD4505 - Asunt Publ y Comunid","","000") -> AMSA1003AD4505 - Asunt Publ y Comunid | B18: =IFERROR(SUBSTITUTE(TRIM(LEFT(A18,FIND("-",A18)-1)),"AMSA",""),"") -> 1003AD4505 | C18: =IFERROR(_xlfn.XLOOKUP(B18,'CECOS Corporativos'!$D:$D,'CECOS Corporativos'!$E:$E,""),"") -> Asuntos Públicos y Comunidades | D18: =IFERROR(_xlfn.XLOOKUP(B18,'CECOS Corporativos'!$D:$D,'CECOS Corporativos'!$J:$J,""),"") -> VP Asuntos Corporativos | E18: =_xll.EPMOlapMemberO("[CLACO].[PARENTH7].[AMSALIQUIDACIO.SEC]","","Liquidación Interna","","000") -> Liquidación Interna | F18: =IFERROR(TRIM(LEFT(G18,FIND("-",G18)-1)),"") -> N100300500 | G18: N100300500 - Antucoya No Operacio | H18: =IFERROR(_xlfn.XLOOKUP(F18,'CECOS Corporativos'!$K:$K,'CECOS Corporativos'!$D:$D,""),"") -> 1003AD4505 | K18: =J18-I18 -> 0 | N18: =M18-L18 -> 0 | Q18: =P18-O18 -> 0 | R18: 2770.78 | T18: =S18-R18 -> -2770.78
A19: =_xll.EPMOlapMemberO("[CECO].[PARENTH3].[AMSA1003AD4505]","","AMSA1003AD4505 - Asunt Publ y Comunid","","000") -> AMSA1003AD4505 - Asunt Publ y Comunid | B19: =IFERROR(SUBSTITUTE(TRIM(LEFT(A19,FIND("-",A19)-1)),"AMSA",""),"") -> 1003AD4505 | C19: =IFERROR(_xlfn.XLOOKUP(B19,'CECOS Corporativos'!$D:$D,'CECOS Corporativos'!$E:$E,""),"") -> Asuntos Públicos y Comunidades | D19: =IFERROR(_xlfn.XLOOKUP(B19,'CECOS Corporativos'!$D:$D,'CECOS Corporativos'!$J:$J,""),"") -> VP Asuntos Corporativos | E19: =_xll.EPMOlapMemberO("[CLACO].[PARENTH7].[AMSASERV_CORP]","","Servicios Corporativ","","000") -> Servicios Corporativ | F19: =IFERROR(TRIM(LEFT(G19,FIND("-",G19)-1)),"") -> N100300500 | G19: N100300500 - Antucoya No Operacio | H19: =IFERROR(_xlfn.XLOOKUP(F19,'CECOS Corporativos'!$K:$K,'CECOS Corporativos'!$D:$D,""),"") -> 1003AD4505 | I19: 424984.07 | J19: 438111 | K19: =J19-I19 -> 13126.93 | L19: 603209.21 | M19: 547565 | N19: =M19-L19 -> -55644.21 | O19: 14533.79 | Q19: =P19-O19 -> -14533.79 | T19: =S19-R19 -> 0
A20: =_xll.EPMOlapMemberO("[CECO].[PARENTH3].[AMSA1003AD4509]","","AMSA1003AD4509 - AAPP Corporativo","","000") -> AMSA1003AD4509 - AAPP Corporativo | B20: =IFERROR(SUBSTITUTE(TRIM(LEFT(A20,FIND("-",A20)-1)),"AMSA",""),"") -> 1003AD4509 | C20: =IFERROR(_xlfn.XLOOKUP(B20,'CECOS Corporativos'!$D:$D,'CECOS Corporativos'!$E:$E,""),"") -> AAPP Corporativo | D20: =IFERROR(_xlfn.XLOOKUP(B20,'CECOS Corporativos'!$D:$D,'CECOS Corporativos'!$J:$J,""),"") -> VP Asuntos Corporativos | E20: =_xll.EPMOlapMemberO("[CLACO].[PARENTH7].[AMSAASESORIAS]","","Asesorías y Consulto","","000") -> Asesorías y Consulto | F20: =IFERROR(TRIM(LEFT(G20,FIND("-",G20)-1)),"") -> N100300500 | G20: N100300500 - Antucoya No Operacio | H20: =IFERROR(_xlfn.XLOOKUP(F20,'CECOS Corporativos'!$K:$K,'CECOS Corporativos'!$D:$D,""),"") -> 1003AD4505 | K20: =J20-I20 -> 0 | M20: 43671 | N20: =M20-L20 -> 43671 | O20: 37752.3 | P20: 29594 | Q20: =P20-O20 -> -8158.3 | R20: 43338.26 | S20: 28730.53 | T20: =S20-R20 -> -14607.73
A21: =_xll.EPMOlapMemberO("[CECO].[PARENTH3].[AMSA1003AD4509]","","AMSA1003AD4509 - AAPP Corporativo","","000") -> AMSA1003AD4509 - AAPP Corporativo | B21: =IFERROR(SUBSTITUTE(TRIM(LEFT(A21,FIND("-",A21)-1)),"AMSA",""),"") -> 1003AD4509 | C21: =IFERROR(_xlfn.XLOOKUP(B21,'CECOS Corporativos'!$D:$D,'CECOS Corporativos'!$E:$E,""),"") -> AAPP Corporativo | D21: =IFERROR(_xlfn.XLOOKUP(B21,'CECOS Corporativos'!$D:$D,'CECOS Corporativos'!$J:$J,""),"") -> VP Asuntos Corporativos | E21: =_xll.EPMOlapMemberO("[CLACO].[PARENTH7].[AMSASERVICIOS]","","Servicios","","000") -> Servicios | F21: =IFERROR(TRIM(LEFT(G21,FIND("-",G21)-1)),"") -> N100300500 | G21: N100300500 - Antucoya No Operacio | H21: =IFERROR(_xlfn.XLOOKUP(F21,'CECOS Corporativos'!$K:$K,'CECOS Corporativos'!$D:$D,""),"") -> 1003AD4505 | K21: =J21-I21 -> 0 | M21: 61271 | N21: =M21-L21 -> 61271 | Q21: =P21-O21 -> 0 | T21: =S21-R21 -> 0
A22: =_xll.EPMOlapMemberO("[CECO].[PARENTH3].[AMSA1003AD4509]","","AMSA1003AD4509 - AAPP Corporativo","","000") -> AMSA1003AD4509 - AAPP Corporativo | B22: =IFERROR(SUBSTITUTE(TRIM(LEFT(A22,FIND("-",A22)-1)),"AMSA",""),"") -> 1003AD4509 | C22: =IFERROR(_xlfn.XLOOKUP(B22,'CECOS Corporativos'!$D:$D,'CECOS Corporativos'!$E:$E,""),"") -> AAPP Corporativo | D22: =IFERROR(_xlfn.XLOOKUP(B22,'CECOS Corporativos'!$D:$D,'CECOS Corporativos'!$J:$J,""),"") -> VP Asuntos Corporativos | E22: =_xll.EPMOlapMemberO("[CLACO].[PARENTH7].[AMSAINFORMATIC]","","Informática y Comuni","","000") -> Informática y Comuni | F22: =IFERROR(TRIM(LEFT(G22,FIND("-",G22)-1)),"") -> N100300500 | G22: N100300500 - Antucoya No Operacio | H22: =IFERROR(_xlfn.XLOOKUP(F22,'CECOS Corporativos'!$K:$K,'CECOS Corporativos'!$D:$D,""),"") -> 1003AD4505 | K22: =J22-I22 -> 0 | M22: 4681 | N22: =M22-L22 -> 4681 | Q22: =P22-O22 -> 0 | T22: =S22-R22 -> 0
A23: =_xll.EPMOlapMemberO("[CECO].[PARENTH3].[AMSA1003AD4509]","","AMSA1003AD4509 - AAPP Corporativo","","000") -> AMSA1003AD4509 - AAPP Corporativo | B23: =IFERROR(SUBSTITUTE(TRIM(LEFT(A23,FIND("-",A23)-1)),"AMSA",""),"") -> 1003AD4509 | C23: =IFERROR(_xlfn.XLOOKUP(B23,'CECOS Corporativos'!$D:$D,'CECOS Corporativos'!$E:$E,""),"") -> AAPP Corporativo | D23: =IFERROR(_xlfn.XLOOKUP(B23,'CECOS Corporativos'!$D:$D,'CECOS Corporativos'!$J:$J,""),"") -> VP Asuntos Corporativos | E23: =_xll.EPMOlapMemberO("[CLACO].[PARENTH7].[AMSAGGENERALES.2]","","Otros Gastos","","000") -> Otros Gastos | F23: =IFERROR(TRIM(LEFT(G23,FIND("-",G23)-1)),"") -> N100300500 | G23: N100300500 - Antucoya No Operacio | H23: =IFERROR(_xlfn.XLOOKUP(F23,'CECOS Corporativos'!$K:$K,'CECOS Corporativos'!$D:$D,""),"") -> 1003AD4505 | K23: =J23-I23 -> 0 | M23: 43383 | N23: =M23-L23 -> 43383 | Q23: =P23-O23 -> 0 | R23: 4819.5 | S23: 8611.28 | T23: =S23-R23 -> 3791.78
A24: =_xll.EPMOlapMemberO("[CECO].[PARENTH3].[AMSA1003AD4510]","","AMSA1003AD4510 - Comunicaciones Corpo","","000") -> AMSA1003AD4510 - Comunicaciones Corpo | B24: =IFERROR(SUBSTITUTE(TRIM(LEFT(A24,FIND("-",A24)-1)),"AMSA",""),"") -> 1003AD4510 | C24: =IFERROR(_xlfn.XLOOKUP(B24,'CECOS Corporativos'!$D:$D,'CECOS Corporativos'!$E:$E,""),"") -> Comunicaciones Corporativo | D24: =IFERROR(_xlfn.XLOOKUP(B24,'CECOS Corporativos'!$D:$D,'CECOS Corporativos'!$J:$J,""),"") -> VP Asuntos Corporativos | E24: =_xll.EPMOlapMemberO("[CLACO].[PARENTH7].[AMSAASESORIAS]","","Asesorías y Consulto","","000") -> Asesorías y Consulto | F24: =IFERROR(TRIM(LEFT(G24,FIND("-",G24)-1)),"") -> N100300500 | G24: N100300500 - Antucoya No Operacio | H24: =IFERROR(_xlfn.XLOOKUP(F24,'CECOS Corporativos'!$K:$K,'CECOS Corporativos'!$D:$D,""),"") -> 1003AD4505 | K24: =J24-I24 -> 0 | M24: 4736 | N24: =M24-L24 -> 4736 | O24: 16139.91 | P24: 8666 | Q24: =P24-O24 -> -7473.91 | R24: 917.75 | T24: =S24-R24 -> -917.75
A25: =_xll.EPMOlapMemberO("[CECO].[PARENTH3].[AMSA1003AD4510]","","AMSA1003AD4510 - Comunicaciones Corpo","","000") -> AMSA1003AD4510 - Comunicaciones Corpo | B25: =IFERROR(SUBSTITUTE(TRIM(LEFT(A25,FIND("-",A25)-1)),"AMSA",""),"") -> 1003AD4510 | C25: =IFERROR(_xlfn.XLOOKUP(B25,'CECOS Corporativos'!$D:$D,'CECOS Corporativos'!$E:$E,""),"") -> Comunicaciones Corporativo | D25: =IFERROR(_xlfn.XLOOKUP(B25,'CECOS Corporativos'!$D:$D,'CECOS Corporativos'!$J:$J,""),"") -> VP Asuntos Corporativos | E25: =_xll.EPMOlapMemberO("[CLACO].[PARENTH7].[AMSAINFORMATIC]","","Informática y Comuni","","000") -> Informática y Comuni | F25: =IFERROR(TRIM(LEFT(G25,FIND("-",G25)-1)),"") -> N100300500 | G25: N100300500 - Antucoya No Operacio | H25: =IFERROR(_xlfn.XLOOKUP(F25,'CECOS Corporativos'!$K:$K,'CECOS Corporativos'!$D:$D,""),"") -> 1003AD4505 | K25: =J25-I25 -> 0 | M25: 13713 | N25: =M25-L25 -> 13713 | P25: 8888 | Q25: =P25-O25 -> 8888 | R25: 2909.19 | S25: 19771.32 | T25: =S25-R25 -> 16862.13
A26: =_xll.EPMOlapMemberO("[CECO].[PARENTH3].[AMSA1003AD4510]","","AMSA1003AD4510 - Comunicaciones Corpo","","000") -> AMSA1003AD4510 - Comunicaciones Corpo | B26: =IFERROR(SUBSTITUTE(TRIM(LEFT(A26,FIND("-",A26)-1)),"AMSA",""),"") -> 1003AD4510 | C26: =IFERROR(_xlfn.XLOOKUP(B26,'CECOS Corporativos'!$D:$D,'CECOS Corporativos'!$E:$E,""),"") -> Comunicaciones Corporativo | D26: =IFERROR(_xlfn.XLOOKUP(B26,'CECOS Corporativos'!$D:$D,'CECOS Corporativos'!$J:$J,""),"") -> VP Asuntos Corporativos | E26: =_xll.EPMOlapMemberO("[CLACO].[PARENTH7].[AMSAGGENERALES.2]","","Otros Gastos","","000") -> Otros Gastos | F26: =IFERROR(TRIM(LEFT(G26,FIND("-",G26)-1)),"") -> N100300500 | G26: N100300500 - Antucoya No Operacio | H26: =IFERROR(_xlfn.XLOOKUP(F26,'CECOS Corporativos'!$K:$K,'CECOS Corporativos'!$D:$D,""),"") -> 1003AD4505 | K26: =J26-I26 -> 0 | M26: 22307 | N26: =M26-L26 -> 22307 | O26: 41968.58 | P26: 48594 | Q26: =P26-O26 -> 6625.42 | R26: 85781.4 | S26: 61736.33 | T26: =S26-R26 -> -24045.07
A27: =_xll.EPMOlapMemberO("[CECO].[PARENTH3].[AMSA1003AD4512]","","AMSA1003AD4512 - AAPP y RRII","","000") -> AMSA1003AD4512 - AAPP y RRII | B27: =IFERROR(SUBSTITUTE(TRIM(LEFT(A27,FIND("-",A27)-1)),"AMSA",""),"") -> 1003AD4512 | C27: =IFERROR(_xlfn.XLOOKUP(B27,'CECOS Corporativos'!$D:$D,'CECOS Corporativos'!$E:$E,""),"") -> AAPP y RRII | D27: =IFERROR(_xlfn.XLOOKUP(B27,'CECOS Corporativos'!$D:$D,'CECOS Corporativos'!$J:$J,""),"") -> VP Asuntos Corporativos | E27: =_xll.EPMOlapMemberO("[CLACO].[PARENTH7].[AMSAASESORIAS]","","Asesorías y Consulto","","000") -> Asesorías y Consulto | F27: =IFERROR(TRIM(LEFT(G27,FIND("-",G27)-1)),"") -> N100300500 | G27: N100300500 - Antucoya No Operacio | H27: =IFERROR(_xlfn.XLOOKUP(F27,'CECOS Corporativos'!$K:$K,'CECOS Corporativos'!$D:$D,""),"") -> 1003AD4505 | K27: =J27-I27 -> 0 | N27: =M27-L27 -> 0 | Q27: =P27-O27 -> 0 | R27: 20884.4 | T27: =S27-R27 -> -20884.4
A28: =_xll.EPMOlapMemberO("[CECO].[PARENTH3].[AMSA1003AD4512]","","AMSA1003AD4512 - AAPP y RRII","","000") -> AMSA1003AD4512 - AAPP y RRII | B28: =IFERROR(SUBSTITUTE(TRIM(LEFT(A28,FIND("-",A28)-1)),"AMSA",""),"") -> 1003AD4512 | C28: =IFERROR(_xlfn.XLOOKUP(B28,'CECOS Corporativos'!$D:$D,'CECOS Corporativos'!$E:$E,""),"") -> AAPP y RRII | D28: =IFERROR(_xlfn.XLOOKUP(B28,'CECOS Corporativos'!$D:$D,'CECOS Corporativos'!$J:$J,""),"") -> VP Asuntos Corporativos | E28: =_xll.EPMOlapMemberO("[CLACO].[PARENTH7].[AMSASERVICIOS]","","Servicios","","000") -> Servicios | F28: =IFERROR(TRIM(LEFT(G28,FIND("-",G28)-1)),"") -> N100300500 | G28: N100300500 - Antucoya No Operacio | H28: =IFERROR(_xlfn.XLOOKUP(F28,'CECOS Corporativos'!$K:$K,'CECOS Corporativos'!$D:$D,""),"") -> 1003AD4505 | K28: =J28-I28 -> 0 | M28: 34884 | N28: =M28-L28 -> 34884 | O28: 0 | P28: 40750 | Q28: =P28-O28 -> 40750 | R28: 2183.03 | S28: 6284.96 | T28: =S28-R28 -> 4101.93
A29: =_xll.EPMOlapMemberO("[CECO].[PARENTH3].[AMSA1003AD4512]","","AMSA1003AD4512 - AAPP y RRII","","000") -> AMSA1003AD4512 - AAPP y RRII | B29: =IFERROR(SUBSTITUTE(TRIM(LEFT(A29,FIND("-",A29)-1)),"AMSA",""),"") -> 1003AD4512 | C29: =IFERROR(_xlfn.XLOOKUP(B29,'CECOS Corporativos'!$D:$D,'CECOS Corporativos'!$E:$E,""),"") -> AAPP y RRII | D29: =IFERROR(_xlfn.XLOOKUP(B29,'CECOS Corporativos'!$D:$D,'CECOS Corporativos'!$J:$J,""),"") -> VP Asuntos Corporativos | E29: =_xll.EPMOlapMemberO("[CLACO].[PARENTH7].[AMSAINFORMATIC]","","Informática y Comuni","","000") -> Informática y Comuni | F29: =IFERROR(TRIM(LEFT(G29,FIND("-",G29)-1)),"") -> N100300500 | G29: N100300500 - Antucoya No Operacio | H29: =IFERROR(_xlfn.XLOOKUP(F29,'CECOS Corporativos'!$K:$K,'CECOS Corporativos'!$D:$D,""),"") -> 1003AD4505 | K29: =J29-I29 -> 0 | N29: =M29-L29 -> 0 | O29: 8067.77 | P29: 6060 | Q29: =P29-O29 -> -2007.77 | R29: 1827.2 | T29: =S29-R29 -> -1827.2
A30: =_xll.EPMOlapMemberO("[CECO].[PARENTH3].[AMSA1003AD4512]","","AMSA1003AD4512 - AAPP y RRII","","000") -> AMSA1003AD4512 - AAPP y RRII | B30: =IFERROR(SUBSTITUTE(TRIM(LEFT(A30,FIND("-",A30)-1)),"AMSA",""),"") -> 1003AD4512 | C30: =IFERROR(_xlfn.XLOOKUP(B30,'CECOS Corporativos'!$D:$D,'CECOS Corporativos'!$E:$E,""),"") -> AAPP y RRII | D30: =IFERROR(_xlfn.XLOOKUP(B30,'CECOS Corporativos'!$D:$D,'CECOS Corporativos'!$J:$J,""),"") -> VP Asuntos Corporativos | E30: =_xll.EPMOlapMemberO("[CLACO].[PARENTH7].[AMSAGGENERALES.2]","","Otros Gastos","","000") -> Otros Gastos | F30: =IFERROR(TRIM(LEFT(G30,FIND("-",G30)-1)),"") -> N100300500 | G30: N100300500 - Antucoya No Operacio | H30: =IFERROR(_xlfn.XLOOKUP(F30,'CECOS Corporativos'!$K:$K,'CECOS Corporativos'!$D:$D,""),"") -> 1003AD4505 | K30: =J30-I30 -> 0 | L30: 11763.98 | M30: 102191 | N30: =M30-L30 -> 90427.02 | O30: 100366.71 | P30: 48972 | Q30: =P30-O30 -> -51394.71 | R30: 30256.64 | S30: 26601.59 | T30: =S30-R30 -> -3655.05
A31: =_xll.EPMOlapMemberO("[CECO].[PARENTH3].[AMSA1003AD0503]","","AMSA1003AD0503 - Corporativo","","000") -> AMSA1003AD0503 - Corporativo | B31: =IFERROR(SUBSTITUTE(TRIM(LEFT(A31,FIND("-",A31)-1)),"AMSA",""),"") -> 1003AD0503 | C31: =IFERROR(_xlfn.XLOOKUP(B31,'CECOS Corporativos'!$D:$D,'CECOS Corporativos'!$E:$E,""),"") -> Auditoría (HH Corporativo) | D31: =IFERROR(_xlfn.XLOOKUP(B31,'CECOS Corporativos'!$D:$D,'CECOS Corporativos'!$J:$J,""),"") -> Auditoría (HH Corporativo) | E31: =_xll.EPMOlapMemberO("[CLACO].[PARENTH7].[AMSAASESORIAS]","","Asesorías y Consulto","","000") -> Asesorías y Consulto | F31: =IFERROR(TRIM(LEFT(G31,FIND("-",G31)-1)),"") -> N1003AD050 | G31: N1003AD050 - Gerencia General | H31: =IFERROR(_xlfn.XLOOKUP(F31,'CECOS Corporativos'!$K:$K,'CECOS Corporativos'!$D:$D,""),"") -> 1003AD0508 | I31: -13231.9 | K31: =J31-I31 -> 13231.9 | N31: =M31-L31 -> 0 | Q31: =P31-O31 -> 0 | T31: =S31-R31 -> 0
A32: =_xll.EPMOlapMemberO("[CECO].[PARENTH3].[AMSA1003AD0503]","","AMSA1003AD0503 - Corporativo","","000") -> AMSA1003AD0503 - Corporativo | B32: =IFERROR(SUBSTITUTE(TRIM(LEFT(A32,FIND("-",A32)-1)),"AMSA",""),"") -> 1003AD0503 | C32: =IFERROR(_xlfn.XLOOKUP(B32,'CECOS Corporativos'!$D:$D,'CECOS Corporativos'!$E:$E,""),"") -> Auditoría (HH Corporativo) | D32: =IFERROR(_xlfn.XLOOKUP(B32,'CECOS Corporativos'!$D:$D,'CECOS Corporativos'!$J:$J,""),"") -> Auditoría (HH Corporativo) | E32: =_xll.EPMOlapMemberO("[CLACO].[PARENTH7].[AMSASERMANTO.REPA]","","Servicios Mantenimie","","000") -> Servicios Mantenimie | F32: =IFERROR(TRIM(LEFT(G32,FIND("-",G32)-1)),"") -> N1003AD050 | G32: N1003AD050 - Gerencia General | H32: =IFERROR(_xlfn.XLOOKUP(F32,'CECOS Corporativos'!$K:$K,'CECOS Corporativos'!$D:$D,""),"") -> 1003AD0508 | K32: =J32-I32 -> 0 | N32: =M32-L32 -> 0 | Q32: =P32-O32 -> 0 | R32: 16.97 | T32: =S32-R32 -> -16.97
A33: =_xll.EPMOlapMemberO("[CECO].[PARENTH3].[AMSA1003AD0503]","","AMSA1003AD0503 - Corporativo","","000") -> AMSA1003AD0503 - Corporativo | B33: =IFERROR(SUBSTITUTE(TRIM(LEFT(A33,FIND("-",A33)-1)),"AMSA",""),"") -> 1003AD0503 | C33: =IFERROR(_xlfn.XLOOKUP(B33,'CECOS Corporativos'!$D:$D,'CECOS Corporativos'!$E:$E,""),"") -> Auditoría (HH Corporativo) | D33: =IFERROR(_xlfn.XLOOKUP(B33,'CECOS Corporativos'!$D:$D,'CECOS Corporativos'!$J:$J,""),"") -> Auditoría (HH Corporativo) | E33: =_xll.EPMOlapMemberO("[CLACO].[PARENTH7].[AMSAG_VIAJES]","","Gastos de Viajes","","000") -> Gastos de Viajes | F33: =IFERROR(TRIM(LEFT(G33,FIND("-",G33)-1)),"") -> N1003AD050 | G33: N1003AD050 - Gerencia General | H33: =IFERROR(_xlfn.XLOOKUP(F33,'CECOS Corporativos'!$K:$K,'CECOS Corporativos'!$D:$D,""),"") -> 1003AD0508 | I33: 0 | K33: =J33-I33 -> 0 | N33: =M33-L33 -> 0 | Q33: =P33-O33 -> 0 | T33: =S33-R33 -> 0
A34: =_xll.EPMOlapMemberO("[CECO].[PARENTH3].[AMSA1003AD0503]","","AMSA1003AD0503 - Corporativo","","000") -> AMSA1003AD0503 - Corporativo | B34: =IFERROR(SUBSTITUTE(TRIM(LEFT(A34,FIND("-",A34)-1)),"AMSA",""),"") -> 1003AD0503 | C34: =IFERROR(_xlfn.XLOOKUP(B34,'CECOS Corporativos'!$D:$D,'CECOS Corporativos'!$E:$E,""),"") -> Auditoría (HH Corporativo) | D34: =IFERROR(_xlfn.XLOOKUP(B34,'CECOS Corporativos'!$D:$D,'CECOS Corporativos'!$J:$J,""),"") -> Auditoría (HH Corporativo) | E34: =_xll.EPMOlapMemberO("[CLACO].[PARENTH7].[AMSASERV_CORP]","","Servicios Corporativ","","000") -> Servicios Corporativ | F34: =IFERROR(TRIM(LEFT(G34,FIND("-",G34)-1)),"") -> N1003AD050 | G34: N1003AD050 - Gerencia General | H34: =IFERROR(_xlfn.XLOOKUP(F34,'CECOS Corporativos'!$K:$K,'CECOS Corporativos'!$D:$D,""),"") -> 1003AD0508 | I34: 385777.39 | J34: 397697 | K34: =J34-I34 -> 11919.61 | L34: 457194.15 | M34: 416198 | N34: =M34-L34 -> -40996.15 | O34: 185195.85 | P34: 184267 | Q34: =P34-O34 -> -928.85 | R34: 223942 | S34: 235062.76 | T34: =S34-R34 -> 11120.76
A35: =_xll.EPMOlapMemberO("[CECO].[PARENTH3].[AMSA1003AD0504]","","AMSA1003AD0504 - Desarrollo Corp","","000") -> AMSA1003AD0504 - Desarrollo Corp | B35: =IFERROR(SUBSTITUTE(TRIM(LEFT(A35,FIND("-",A35)-1)),"AMSA",""),"") -> 1003AD0504 | C35: =IFERROR(_xlfn.XLOOKUP(B35,'CECOS Corporativos'!$D:$D,'CECOS Corporativos'!$E:$E,""),"") -> VP Desarrollo | D35: =IFERROR(_xlfn.XLOOKUP(B35,'CECOS Corporativos'!$D:$D,'CECOS Corporativos'!$J:$J,""),"") -> VP Desarrollo | E35: =_xll.EPMOlapMemberO("[CLACO].[PARENTH7].[AMSAASESORIAS]","","Asesorías y Consulto","","000") -> Asesorías y Consulto | F35: =IFERROR(TRIM(LEFT(G35,FIND("-",G35)-1)),"") -> N1003AD050 | G35: N1003AD050 - Gerencia General | H35: =IFERROR(_xlfn.XLOOKUP(F35,'CECOS Corporativos'!$K:$K,'CECOS Corporativos'!$D:$D,""),"") -> 1003AD0508 | I35: 52498.85 | K35: =J35-I35 -> -52498.85 | L35: 67660.5 | M35: 40784 | N35: =M35-L35 -> -26876.5 | O35: -3302.73 | Q35: =P35-O35 -> 3302.73 | T35: =S35-R35 -> 0
A36: =_xll.EPMOlapMemberO("[CECO].[PARENTH3].[AMSA1003AD0504]","","AMSA1003AD0504 - Desarrollo Corp","","000") -> AMSA1003AD0504 - Desarrollo Corp | B36: =IFERROR(SUBSTITUTE(TRIM(LEFT(A36,FIND("-",A36)-1)),"AMSA",""),"") -> 1003AD0504 | C36: =IFERROR(_xlfn.XLOOKUP(B36,'CECOS Corporativos'!$D:$D,'CECOS Corporativos'!$E:$E,""),"") -> VP Desarrollo | D36: =IFERROR(_xlfn.XLOOKUP(B36,'CECOS Corporativos'!$D:$D,'CECOS Corporativos'!$J:$J,""),"") -> VP Desarrollo | E36: =_xll.EPMOlapMemberO("[CLACO].[PARENTH7].[AMSASERVICIOS]","","Servicios","","000") -> Servicios | F36: =IFERROR(TRIM(LEFT(G36,FIND("-",G36)-1)),"") -> N1003AD050 | G36: N1003AD050 - Gerencia General | H36: =IFERROR(_xlfn.XLOOKUP(F36,'CECOS Corporativos'!$K:$K,'CECOS Corporativos'!$D:$D,""),"") -> 1003AD0508 | K36: =J36-I36 -> 0 | L36: 178.41 | N36: =M36-L36 -> -178.41 | Q36: =P36-O36 -> 0 | R36: -38500 | T36: =S36-R36 -> 38500
A37: =_xll.EPMOlapMemberO("[CECO].[PARENTH3].[AMSA1003AD0504]","","AMSA1003AD0504 - Desarrollo Corp","","000") -> AMSA1003AD0504 - Desarrollo Corp | B37: =IFERROR(SUBSTITUTE(TRIM(LEFT(A37,FIND("-",A37)-1)),"AMSA",""),"") -> 1003AD0504 | C37: =IFERROR(_xlfn.XLOOKUP(B37,'CECOS Corporativos'!$D:$D,'CECOS Corporativos'!$E:$E,""),"") -> VP Desarrollo | D37: =IFERROR(_xlfn.XLOOKUP(B37,'CECOS Corporativos'!$D:$D,'CECOS Corporativos'!$J:$J,""),"") -> VP Desarrollo | E37: =_xll.EPMOlapMemberO("[CLACO].[PARENTH7].[AMSASERMANTO.REPA]","","Servicios Mantenimie","","000") -> Servicios Mantenimie | F37: =IFERROR(TRIM(LEFT(G37,FIND("-",G37)-1)),"") -> N1003AD050 | G37: N1003AD050 - Gerencia General | H37: =IFERROR(_xlfn.XLOOKUP(F37,'CECOS Corporativos'!$K:$K,'CECOS Corporativos'!$D:$D,""),"") -> 1003AD0508 | K37: =J37-I37 -> 0 | N37: =M37-L37 -> 0 | Q37: =P37-O37 -> 0 | R37: 2211.36 | T37: =S37-R37 -> -2211.36
A38: =_xll.EPMOlapMemberO("[CECO].[PARENTH3].[AMSA1003AD0504]","","AMSA1003AD0504 - Desarrollo Corp","","000") -> AMSA1003AD0504 - Desarrollo Corp | B38: =IFERROR(SUBSTITUTE(TRIM(LEFT(A38,FIND("-",A38)-1)),"AMSA",""),"") -> 1003AD0504 | C38: =IFERROR(_xlfn.XLOOKUP(B38,'CECOS Corporativos'!$D:$D,'CECOS Corporativos'!$E:$E,""),"") -> VP Desarrollo | D38: =IFERROR(_xlfn.XLOOKUP(B38,'CECOS Corporativos'!$D:$D,'CECOS Corporativos'!$J:$J,""),"") -> VP Desarrollo | E38: =_xll.EPMOlapMemberO("[CLACO].[PARENTH7].[AMSAINFORMATIC]","","Informática y Comuni","","000") -> Informática y Comuni | F38: =IFERROR(TRIM(LEFT(G38,FIND("-",G38)-1)),"") -> N1003AD050 | G38: N1003AD050 - Gerencia General | H38: =IFERROR(_xlfn.XLOOKUP(F38,'CECOS Corporativos'!$K:$K,'CECOS Corporativos'!$D:$D,""),"") -> 1003AD0508 | K38: =J38-I38 -> 0 | N38: =M38-L38 -> 0 | O38: 7733.47 | Q38: =P38-O38 -> -7733.47 | R38: 12358.67 | S38: 12523.96 | T38: =S38-R38 -> 165.29
