Workbook

Sheet Consolidado Propios
A1: Dotación Histórica AMSA — Consolidado por Vicepresidencia y Gerencia 2022–2026
A2: Dotación Propia Actividad Corporativa · Promedio anual (N°) · Real vs Presupuesto
A4: Vicepresidencia / Gerencia | B4: 2022 | D4: 2023 | F4: 2024 | H4: 2025 | J4: 2026 YTD | L4: 2026 FY
B5: Real | C5: Ppto | D5: Real | E5: Ppto | F5: Real | G5: Ppto | H5: Real | I5: Ppto | J5: Real | K5: Ppto | L5: Ppto
A6: Auditoria | B6: =IF(COUNT(B7:B7)=0,"",SUM(B7:B7)) -> 11.666667 | C6: =IF(COUNT(C7:C7)=0,"",SUM(C7:C7)) -> 12 | D6: =IF(COUNT(D7:D7)=0,"",SUM(D7:D7)) -> 11.5 | E6: =IF(COUNT(E7:E7)=0,"",SUM(E7:E7)) -> 12 | F6: =IF(COUNT(F7:F7)=0,"",SUM(F7:F7)) -> 13.416667 | G6: =IF(COUNT(G7:G7)=0,"",SUM(G7:G7)) -> 14 | H6: =IF(COUNT(H7:H7)=0,"",SUM(H7:H7)) -> 14.416667 | I6: =IF(COUNT(I7:I7)=0,"",SUM(I7:I7)) -> 15 | ... L6: =IF(COUNT(L7:L7)=0,"",SUM(L7:L7)) -> 15
A7: Auditoria | B7: =IFERROR(AVERAGE('2022'!H8:S8),"") -> 11.666667 | C7: =IFERROR(AVERAGE('2022'!H9:S9),"") -> 12 | D7: =IFERROR(AVERAGE('2023'!G7:R7),"") -> 11.5 | E7: =IFERROR(AVERAGE('2023'!G8:R8),"") -> 12 | F7: =IFERROR(AVERAGE('2024'!G7:R7),"") -> 13.416667 | G7: =IFERROR(AVERAGE('2024'!G8:R8),"") -> 14 | H7: =IFERROR(AVERAGE('2025'!G7:R7),"") -> 14.416667 | I7: =IFERROR(AVERAGE('2025'!G8:R8),"") -> 15 | J7: =IFERROR(AVERAGE('2026'!G7:K7),"") -> 15 | K7: =IFERROR(AVERAGE('2026'!G8:K8),"") -> 15 | L7: =IFERROR(AVERAGE('2026'!G8:R8),"") -> 15
A8: Directorio | B8: =IF(COUNT(B9:B9)=0,"",SUM(B9:B9)) -> 3 | C8: =IF(COUNT(C9:C9)=0,"",SUM(C9:C9)) -> 3 | D8: =IF(COUNT(D9:D9)=0,"",SUM(D9:D9)) -> 3 | E8: =IF(COUNT(E9:E9)=0,"",SUM(E9:E9)) -> 3 | F8: =IF(COUNT(F9:F9)=0,"",SUM(F9:F9)) -> 3 | G8: =IF(COUNT(G9:G9)=0,"",SUM(G9:G9)) -> 3 | H8: =IF(COUNT(H9:H9)=0,"",SUM(H9:H9)) -> 3 | I8: =IF(COUNT(I9:I9)=0,"",SUM(I9:I9)) -> 3 | ... L8: =IF(COUNT(L9:L9)=0,"",SUM(L9:L9)) -> 3
A9: Directorio | B9: =IFERROR(AVERAGE('2022'!H10:S10),"") -> 3 | C9: =IFERROR(AVERAGE('2022'!H11:S11),"") -> 3 | D9: =IFERROR(AVERAGE('2023'!G9:R9),"") -> 3 | E9: =IFERROR(AVERAGE('2023'!G10:R10),"") -> 3 | F9: =IFERROR(AVERAGE('2024'!G9:R9),"") -> 3 | G9: =IFERROR(AVERAGE('2024'!G10:R10),"") -> 3 | H9: =IFERROR(AVERAGE('2025'!G9:R9),"") -> 3 | I9: =IFERROR(AVERAGE('2025'!G10:R10),"") -> 3 | J9: =IFERROR(AVERAGE('2026'!G9:K9),"") -> 3 | K9: =IFERROR(AVERAGE('2026'!G10:K10),"") -> 3 | L9: =IFERROR(AVERAGE('2026'!G10:R10),"") -> 3
A10: Presidencia Ejecutiva | B10: =IF(COUNT(B11:B11)=0,"",SUM(B11:B11)) -> 1.8333333 | C10: =IF(COUNT(C11:C11)=0,"",SUM(C11:C11)) -> 2 | D10: =IF(COUNT(D11:D11)=0,"",SUM(D11:D11)) -> 2 | E10: =IF(COUNT(E11:E11)=0,"",SUM(E11:E11)) -> 2 | F10: =IF(COUNT(F11:F11)=0,"",SUM(F11:F11)) -> 2 | G10: =IF(COUNT(G11:G11)=0,"",SUM(G11:G11)) -> 2 | H10: =IF(COUNT(H11:H11)=0,"",SUM(H11:H11)) -> 2 | I10: =IF(COUNT(I11:I11)=0,"",SUM(I11:I11)) -> 2 | ... L10: =IF(COUNT(L11:L11)=0,"",SUM(L11:L11)) -> 2
A11: Presidencia Ejecutiva | B11: =IFERROR(AVERAGE('2022'!H12:S12),"") -> 1.8333333 | C11: =IFERROR(AVERAGE('2022'!H13:S13),"") -> 2 | D11: =IFERROR(AVERAGE('2023'!G11:R11),"") -> 2 | E11: =IFERROR(AVERAGE('2023'!G12:R12),"") -> 2 | F11: =IFERROR(AVERAGE('2024'!G11:R11),"") -> 2 | G11: =IFERROR(AVERAGE('2024'!G12:R12),"") -> 2 | H11: =IFERROR(AVERAGE('2025'!G11:R11),"") -> 2 | I11: =IFERROR(AVERAGE('2025'!G12:R12),"") -> 2 | J11: =IFERROR(AVERAGE('2026'!G11:K11),"") -> 2 | K11: =IFERROR(AVERAGE('2026'!G12:K12),"") -> 2 | L11: =IFERROR(AVERAGE('2026'!G12:R12),"") -> 2
A12: Vicepresidencia Comercialización | B12: =IF(COUNT(B13:B15)=0,"",SUM(B13:B15)) -> 19 | C12: =IF(COUNT(C13:C15)=0,"",SUM(C13:C15)) -> 19 | D12: =IF(COUNT(D13:D15)=0,"",SUM(D13:D15)) -> 18.166667 | E12: =IF(COUNT(E13:E15)=0,"",SUM(E13:E15)) -> 19.083333 | F12: =IF(COUNT(F13:F15)=0,"",SUM(F13:F15)) -> 18.833333 | G12: =IF(COUNT(G13:G15)=0,"",SUM(G13:G15)) -> 19.75 | H12: =IF(COUNT(H13:H15)=0,"",SUM(H13:H15)) -> 18.75 | I12: =IF(COUNT(I13:I15)=0,"",SUM(I13:I15)) -> 20 | ... L12: =IF(COUNT(L13:L15)=0,"",SUM(L13:L15)) -> 19
A13: Ventas Cátodos Molibdeno y Hedge | B13: =IFERROR(AVERAGE('2022'!H28:S28),"") -> 5.25 | C13: =IFERROR(AVERAGE('2022'!H29:S29),"") -> 6 | D13: =IFERROR(AVERAGE('2023'!G27:R27),"") -> 4.1666667 | E13: =IFERROR(AVERAGE('2023'!G28:R28),"") -> 4.25 | F13: =IFERROR(AVERAGE('2024'!G27:R27),"") -> 4.8333333 | G13: =IFERROR(AVERAGE('2024'!G28:R28),"") -> 5.75 | H13: =IFERROR(AVERAGE('2025'!G13:R13),"") -> 5 | I13: =IFERROR(AVERAGE('2025'!G14:R14),"") -> 5 | J13: =IFERROR(AVERAGE('2026'!G13:K13),"") -> 5 | K13: =IFERROR(AVERAGE('2026'!G14:K14),"") -> 5 | L13: =IFERROR(AVERAGE('2026'!G14:R14),"") -> 5
A14: Ventas Concentrado Acido | B14: =IFERROR(AVERAGE('2022'!H30:S30),"") -> 4 | C14: =IFERROR(AVERAGE('2022'!H31:S31),"") -> 3 | D14: =IFERROR(AVERAGE('2023'!G29:R29),"") -> 4 | E14: =IFERROR(AVERAGE('2023'!G30:R30),"") -> 4 | F14: =IFERROR(AVERAGE('2024'!G29:R29),"") -> 4.6666667 | G14: =IFERROR(AVERAGE('2024'!G30:R30),"") -> 4 | H14: =IFERROR(AVERAGE('2025'!G15:R15),"") -> 4.9166667 | I14: =IFERROR(AVERAGE('2025'!G16:R16),"") -> 5 | J14: =IFERROR(AVERAGE('2026'!G15:K15),"") -> 5 | K14: =IFERROR(AVERAGE('2026'!G16:K16),"") -> 5 | L14: =IFERROR(AVERAGE('2026'!G16:R16),"") -> 5
A15: Vicepresidencia Comercialización | B15: =IFERROR(AVERAGE('2022'!H32:S32),"") -> 9.75 | C15: =IFERROR(AVERAGE('2022'!H33:S33),"") -> 10 | D15: =IFERROR(AVERAGE('2023'!G31:R31),"") -> 10 | E15: =IFERROR(AVERAGE('2023'!G32:R32),"") -> 10.833333 | F15: =IFERROR(AVERAGE('2024'!G31:R31),"") -> 9.3333333 | G15: =IFERROR(AVERAGE('2024'!G32:R32),"") -> 10 | H15: =IFERROR(AVERAGE('2025'!G17:R17),"") -> 8.8333333 | I15: =IFERROR(AVERAGE('2025'!G18:R18),"") -> 10 | J15: =IFERROR(AVERAGE('2026'!G17:K17),"") -> 9 | K15: =IFERROR(AVERAGE('2026'!G18:K18),"") -> 9 | L15: =IFERROR(AVERAGE('2026'!G18:R18),"") -> 9
A16: Vicepresidencia de Asuntos Corporativos | B16: =IF(COUNT(B17:B21)=0,"",SUM(B17:B21)) | C16: =IF(COUNT(C17:C21)=0,"",SUM(C17:C21)) | D16: =IF(COUNT(D17:D21)=0,"",SUM(D17:D21)) | E16: =IF(COUNT(E17:E21)=0,"",SUM(E17:E21)) | F16: =IF(COUNT(F17:F21)=0,"",SUM(F17:F21)) -> 19.666667 | G16: =IF(COUNT(G17:G21)=0,"",SUM(G17:G21)) -> 0 | H16: =IF(COUNT(H17:H21)=0,"",SUM(H17:H21)) -> 45.25 | I16: =IF(COUNT(I17:I21)=0,"",SUM(I17:I21)) -> 49 | ... L16: =IF(COUNT(L17:L21)=0,"",SUM(L17:L21)) -> 52
A17: Asuntos Públicos Corporativo | F17: =IFERROR(AVERAGE('2024'!G33:R33),"") -> 1.6666667 | G17: =IFERROR(AVERAGE('2024'!G34:R34),"") -> 0 | H17: =IFERROR(AVERAGE('2025'!G19:R19),"") -> 2.1666667 | I17: =IFERROR(AVERAGE('2025'!G20:R20),"") -> 5
A18: Asuntos Públicos Norte | F18: =IFERROR(AVERAGE('2024'!G37:R37),"") -> 5.5833333 | G18: =IFERROR(AVERAGE('2024'!G38:R38),"") -> 0 | H18: =IFERROR(AVERAGE('2025'!G21:R21),"") -> 12.416667 | I18: =IFERROR(AVERAGE('2025'!G22:R22),"") -> 13 | J18: =IFERROR(AVERAGE('2026'!G21:K21),"") -> 13 | K18: =IFERROR(AVERAGE('2026'!G22:K22),"") -> 15 | L18: =IFERROR(AVERAGE('2026'!G22:R22),"") -> 15
A19: Asuntos Publicos MLP | F19: =IFERROR(AVERAGE('2024'!G35:R35),"") -> 8.0833333 | G19: =IFERROR(AVERAGE('2024'!G36:R36),"") -> 0 | H19: =IFERROR(AVERAGE('2025'!G23:R23),"") -> 18.583333 | I19: =IFERROR(AVERAGE('2025'!G24:R24),"") -> 20 | J19: =IFERROR(AVERAGE('2026'!G19:K19),"") -> 17.4 | K19: =IFERROR(AVERAGE('2026'!G20:K20),"") -> 18 | L19: =IFERROR(AVERAGE('2026'!G20:R20),"") -> 18
A20: Comunicaciones | F20: =IFERROR(AVERAGE('2024'!G39:R39),"") -> 3.3333333 | G20: =IFERROR(AVERAGE('2024'!G40:R40),"") -> 0 | H20: =IFERROR(AVERAGE('2025'!G25:R25),"") -> 7.5833333 | I20: =IFERROR(AVERAGE('2025'!G26:R26),"") -> 8 | J20: =IFERROR(AVERAGE('2026'!G23:K23),"") -> 7.8 | K20: =IFERROR(AVERAGE('2026'!G24:K24),"") -> 8 | L20: =IFERROR(AVERAGE('2026'!G24:R24),"") -> 8
A21: Vicepresidencia Asuntos Corporativos | F21: =IFERROR(AVERAGE('2024'!G41:R41),"") -> 1 | G21: =IFERROR(AVERAGE('2024'!G42:R42),"") -> 0 | H21: =IFERROR(AVERAGE('2025'!G27:R27),"") -> 4.5 | I21: =IFERROR(AVERAGE('2025'!G28:R28),"") -> 3 | J21: =IFERROR(AVERAGE('2026'!G25:K25),"") -> 10.4 | K21: =IFERROR(AVERAGE('2026'!G26:K26),"") -> 11 | L21: =IFERROR(AVERAGE('2026'!G26:R26),"") -> 11
A22: Vicepresidencia de Proyectos | B22: =IF(COUNT(B23:B26)=0,"",SUM(B23:B26)) -> 13.25 | C22: =IF(COUNT(C23:C26)=0,"",SUM(C23:C26)) -> 15 | D22: =IF(COUNT(D23:D26)=0,"",SUM(D23:D26)) -> 12.333333 | E22: =IF(COUNT(E23:E26)=0,"",SUM(E23:E26)) -> 14 | F22: =IF(COUNT(F23:F26)=0,"",SUM(F23:F26)) -> 15 | G22: =IF(COUNT(G23:G26)=0,"",SUM(G23:G26)) -> 14 | H22: =IF(COUNT(H23:H26)=0,"",SUM(H23:H26)) -> 23.666667 | I22: =IF(COUNT(I23:I26)=0,"",SUM(I23:I26)) -> 27 | ... L22: =IF(COUNT(L23:L26)=0,"",SUM(L23:L26)) -> 27
A23: Finanzas VPP | B23: =IFERROR(AVERAGE('2022'!H34:S34),"") -> 7 | C23: =IFERROR(AVERAGE('2022'!H35:S35),"") -> 8 | D23: =IFERROR(AVERAGE('2023'!G33:R33),"") -> 6.1666667 | E23: =IFERROR(AVERAGE('2023'!G34:R34),"") -> 7 | F23: =IFERROR(AVERAGE('2024'!G43:R43),"") -> 7.5833333 | G23: =IFERROR(AVERAGE('2024'!G44:R44),"") -> 7 | H23: =IFERROR(AVERAGE('2025'!G29:R29),"") -> 12.166667 | I23: =IFERROR(AVERAGE('2025'!G30:R30),"") -> 14 | J23: =IFERROR(AVERAGE('2026'!G27:K27),"") -> 13 | K23: =IFERROR(AVERAGE('2026'!G28:K28),"") -> 14 | L23: =IFERROR(AVERAGE('2026'!G28:R28),"") -> 14
A24: Ingenieria y Construccion | B24: =IFERROR(AVERAGE('2022'!H36:S36),"") -> 4 | C24: =IFERROR(AVERAGE('2022'!H37:S37),"") -> 5 | D24: =IFERROR(AVERAGE('2023'!G35:R35),"") -> 4 | E24: =IFERROR(AVERAGE('2023'!G36:R36),"") -> 5 | F24: =IFERROR(AVERAGE('2024'!G45:R45),"") -> 3.3333333 | G24: =IFERROR(AVERAGE('2024'!G46:R46),"") -> 5 | H24: =IFERROR(AVERAGE('2025'!G31:R31),"") -> 2.1666667 | I24: =IFERROR(AVERAGE('2025'!G32:R32),"") -> 5 | J24: =IFERROR(AVERAGE('2026'!G29:K29),"") -> 2 | K24: =IFERROR(AVERAGE('2026'!G30:K30),"") -> 5 | L24: =IFERROR(AVERAGE('2026'!G30:R30),"") -> 5
A25: Proyecto MLP Largo Plazo | F25: =IFERROR(AVERAGE('2024'!G47:R47),"") -> 0 | G25: =IFERROR(AVERAGE('2024'!G48:R48),"") -> 0
A26: Vicepresidencia de Proyectos + Proyecto INCO | B26: =IFERROR(AVERAGE('2022'!H38:S38),"") -> 2.25 | C26: =IFERROR(AVERAGE('2022'!H39:S39),"") -> 2 | D26: =IFERROR(AVERAGE('2023'!G37:R37),"") -> 2.1666667 | E26: =IFERROR(AVERAGE('2023'!G38:R38),"") -> 2 | F26: =IFERROR(AVERAGE('2024'!G49:R49),"") -> 4.0833333 | G26: =IFERROR(AVERAGE('2024'!G50:R50),"") -> 2 | H26: =IFERROR(AVERAGE('2025'!G33:R33),"") -> 9.3333333 | I26: =IFERROR(AVERAGE('2025'!G34:R34),"") -> 8 | J26: =IFERROR(AVERAGE('2026'!G31:K31),"") -> 9.4 | K26: =IFERROR(AVERAGE('2026'!G32:K32),"") -> 8 | L26: =IFERROR(AVERAGE('2026'!G32:R32),"") -> 8
A27: Vicepresidencia Desarrollo | B27: =IF(COUNT(B28:B32)=0,"",SUM(B28:B32)) -> 16.916667 | C27: =IF(COUNT(C28:C32)=0,"",SUM(C28:C32)) -> 17.666667 | D27: =IF(COUNT(D28:D32)=0,"",SUM(D28:D32)) -> 17.333333 | E27: =IF(COUNT(E28:E32)=0,"",SUM(E28:E32)) -> 17.5 | F27: =IF(COUNT(F28:F32)=0,"",SUM(F28:F32)) -> 18.25 | G27: =IF(COUNT(G28:G32)=0,"",SUM(G28:G32)) -> 16.75 | H27: =IF(COUNT(H28:H32)=0,"",SUM(H28:H32)) -> 21.333333 | I27: =IF(COUNT(I28:I32)=0,"",SUM(I28:I32)) -> 22 | ... L27: =IF(COUNT(L28:L32)=0,"",SUM(L28:L32)) -> 21
A28: Administración MIC | B28: =IFERROR(AVERAGE('2022'!H40:S40),"") -> 4.6666667 | C28: =IFERROR(AVERAGE('2022'!H41:S41),"") -> 3.6666667 | D28: =IFERROR(AVERAGE('2023'!G39:R39),"") -> 2.75 | E28: =IFERROR(AVERAGE('2023'!G40:R40),"") -> 3.5 | F28: =IFERROR(AVERAGE('2024'!G51:R51),"") -> 2 | G28: =IFERROR(AVERAGE('2024'!G52:R52),"") -> 2.75 | H28: =IFERROR(AVERAGE('2025'!G35:R35),"") -> 2 | I28: =IFERROR(AVERAGE('2025'!G36:R36),"") -> 3 | J28: =IFERROR(AVERAGE('2026'!G33:K33),"") -> 2 | K28: =IFERROR(AVERAGE('2026'!G34:K34),"") -> 2 | L28: =IFERROR(AVERAGE('2026'!G34:R34),"") -> 2
A29: Desarrollo | B29: =IFERROR(AVERAGE('2022'!H42:S42),"") -> 8 | C29: =IFERROR(AVERAGE('2022'!H43:S43),"") -> 9 | D29: =IFERROR(AVERAGE('2023'!G41:R41),"") -> 9 | E29: =IFERROR(AVERAGE('2023'!G42:R42),"") -> 9 | F29: =IFERROR(AVERAGE('2024'!G53:R53),"") -> 9 | G29: =IFERROR(AVERAGE('2024'!G54:R54),"") -> 9 | H29: =IFERROR(AVERAGE('2025'!G37:R37),"") -> 9 | I29: =IFERROR(AVERAGE('2025'!G38:R38),"") -> 9 | J29: =IFERROR(AVERAGE('2026'!G35:K35),"") -> 8.2 | K29: =IFERROR(AVERAGE('2026'!G36:K36),"") -> 9 | L29: =IFERROR(AVERAGE('2026'!G36:R36),"") -> 9
A30: Exploraciones Global | D30: =IFERROR(AVERAGE('2023'!G43:R43),"") -> 0.5 | E30: =IFERROR(AVERAGE('2023'!G44:R44),"") -> 0
A31: Geología | D31: =IFERROR(AVERAGE('2023'!G45:R45),"") -> 0.25 | E31: =IFERROR(AVERAGE('2023'!G46:R46),"") -> 0
A32: Vicepresidencia Desarrollo | B32: =IFERROR(AVERAGE('2022'!H44:S44),"") -> 4.25 | C32: =IFERROR(AVERAGE('2022'!H45:S45),"") -> 5 | D32: =IFERROR(AVERAGE('2023'!G47:R47),"") -> 4.8333333 | E32: =IFERROR(AVERAGE('2023'!G48:R48),"") -> 5 | F32: =IFERROR(AVERAGE('2024'!G55:R55),"") -> 7.25 | G32: =IFERROR(AVERAGE('2024'!G56:R56),"") -> 5 | H32: =IFERROR(AVERAGE('2025'!G39:R39),"") -> 10.333333 | I32: =IFERROR(AVERAGE('2025'!G40:R40),"") -> 10 | J32: =IFERROR(AVERAGE('2026'!G37:K37),"") -> 7.8 | K32: =IFERROR(AVERAGE('2026'!G38:K38),"") -> 10 | L32: =IFERROR(AVERAGE('2026'!G38:R38),"") -> 10
A33: Vicepresidencia Estrategia e Innovación | B33: =IF(COUNT(B34:B40)=0,"",SUM(B34:B40)) -> 79.083333 | C33: =IF(COUNT(C34:C40)=0,"",SUM(C34:C40)) -> 83.25 | D33: =IF(COUNT(D34:D40)=0,"",SUM(D34:D40)) -> 76 | E33: =IF(COUNT(E34:E40)=0,"",SUM(E34:E40)) -> 85 | F33: =IF(COUNT(F34:F40)=0,"",SUM(F34:F40)) -> 78.666667 | G33: =IF(COUNT(G34:G40)=0,"",SUM(G34:G40)) -> 78.416667 | H33: =IF(COUNT(H34:H40)=0,"",SUM(H34:H40)) -> 75.5 | I33: =IF(COUNT(I34:I40)=0,"",SUM(I34:I40)) -> 80.75 | ... L33: =IF(COUNT(L34:L40)=0,"",SUM(L34:L40)) -> 81
A34: Data y Analítica Avanzada | B34: =IFERROR(AVERAGE('2022'!H46:S46),"") -> 5.1666667 | C34: =IFERROR(AVERAGE('2022'!H47:S47),"") -> 5.25 | D34: =IFERROR(AVERAGE('2023'!G49:R49),"") -> 6.6666667 | E34: =IFERROR(AVERAGE('2023'!G50:R50),"") -> 5 | F34: =IFERROR(AVERAGE('2024'!G57:R57),"") -> 7.75 | G34: =IFERROR(AVERAGE('2024'!G58:R58),"") -> 8 | H34: =IFERROR(AVERAGE('2025'!G41:R41),"") -> 8 | I34: =IFERROR(AVERAGE('2025'!G42:R42),"") -> 8 | J34: =IFERROR(AVERAGE('2026'!G39:K39),"") -> 8.2 | K34: =IFERROR(AVERAGE('2026'!G40:K40),"") -> 8 | L34: =IFERROR(AVERAGE('2026'!G40:R40),"") -> 8
A35: Innovación + Energía y Recursos Hídricos | B35: =IFERROR(AVERAGE('2022'!H50:S50),"") -> 10.166667 | C35: =IFERROR(AVERAGE('2022'!H51:S51),"") -> 12 | D35: =IFERROR(AVERAGE('2023'!G53:R53),"") -> 9.0833333 | E35: =IFERROR(AVERAGE('2023'!G54:R54),"") -> 14 | F35: =IFERROR(AVERAGE('2024'!G59:R59),"") -> 6 | G35: =IFERROR(AVERAGE('2024'!G60:R60),"") -> 6 | H35: =IFERROR(AVERAGE('2025'!G43:R43),"") -> 5.25 | I35: =IFERROR(AVERAGE('2025'!G44:R44),"") -> 6 | J35: =IFERROR(AVERAGE('2026'!G41:K41),"") -> 4.8 | K35: =IFERROR(AVERAGE('2026'!G42:K42),"") -> 5 | L35: =IFERROR(AVERAGE('2026'!G42:R42),"") -> 5
A36: Proyecto Descarbonización | F36: =IFERROR(AVERAGE('2024'!G61:R61),"") -> 4.9166667 | G36: =IFERROR(AVERAGE('2024'!G62:R62),"") -> 0 | H36: =IFERROR(AVERAGE('2025'!G45:R45),"") -> 4.9166667 | I36: =IFERROR(AVERAGE('2025'!G46:R46),"") -> 5 | J36: =IFERROR(AVERAGE('2026'!G43:K43),"") -> 5 | K36: =IFERROR(AVERAGE('2026'!G44:K44),"") -> 5 | L36: =IFERROR(AVERAGE('2026'!G44:R44),"") -> 5
A37: Tecnologia | F37: =IFERROR(AVERAGE('2024'!G63:R63),"") -> 54.166667 | G37: =IFERROR(AVERAGE('2024'!G64:R64),"") -> 55.416667 | H37: =IFERROR(AVERAGE('2025'!G47:R47),"") -> 52.666667 | I37: =IFERROR(AVERAGE('2025'!G48:R48),"") -> 56 | J37: =IFERROR(AVERAGE('2026'!G45:K45),"") -> 51.6 | K37: =IFERROR(AVERAGE('2026'!G46:K46),"") -> 57 | L37: =IFERROR(AVERAGE('2026'!G46:R46),"") -> 57
A38: Estrategia Recursos Mineros | B38: =IFERROR(AVERAGE('2022'!H48:S48),"") -> 3.9166667 | C38: =IFERROR(AVERAGE('2022'!H49:S49),"") -> 4 | D38: =IFERROR(AVERAGE('2023'!G51:R51),"") -> 2 | E38: =IFERROR(AVERAGE('2023'!G52:R52),"") -> 4
A39: TICA | B39: =IFERROR(AVERAGE('2022'!H52:S52),"") -> 53.916667 | C39: =IFERROR(AVERAGE('2022'!H53:S53),"") -> 55 | D39: =IFERROR(AVERAGE('2023'!G55:R55),"") -> 51.583333 | E39: =IFERROR(AVERAGE('2023'!G56:R56),"") -> 56
A40: Vicepresidencia Estrategia e Innovación | B40: =IFERROR(AVERAGE('2022'!H54:S54),"") -> 5.9166667 | C40: =IFERROR(AVERAGE('2022'!H55:S55),"") -> 7 | D40: =IFERROR(AVERAGE('2023'!G57:R57),"") -> 6.6666667 | E40: =IFERROR(AVERAGE('2023'!G58:R58),"") -> 6 | F40: =IFERROR(AVERAGE('2024'!G65:R65),"") -> 5.8333333 | G40: =IFERROR(AVERAGE('2024'!G66:R66),"") -> 9 | H40: =IFERROR(AVERAGE('2025'!G49:R49),"") -> 4.6666667 | I40: =IFERROR(AVERAGE('2025'!G50:R50),"") -> 5.75 | J40: =IFERROR(AVERAGE('2026'!G47:K47),"") -> 4.8 | K40: =IFERROR(AVERAGE('2026'!G48:K48),"") -> 6 | L40: =IFERROR(AVERAGE('2026'!G48:R48),"") -> 6
A41: Vicepresidencia Finanzas | B41: =IF(COUNT(B42:B50)=0,"",SUM(B42:B50)) -> 110.66667 | C41: =IF(COUNT(C42:C50)=0,"",SUM(C42:C50)) -> 114.16667 | D41: =IF(COUNT(D42:D50)=0,"",SUM(D42:D50)) -> 116 | E41: =IF(COUNT(E42:E50)=0,"",SUM(E42:E50)) -> 120.41667 | F41: =IF(COUNT(F42:F50)=0,"",SUM(F42:F50)) -> 121.66667 | G41: =IF(COUNT(G42:G50)=0,"",SUM(G42:G50)) -> 126 | H41: =IF(COUNT(H42:H50)=0,"",SUM(H42:H50)) -> 114.91667 | I41: =IF(COUNT(I42:I50)=0,"",SUM(I42:I50)) -> 128.75 | ... L41: =IF(COUNT(L42:L50)=0,"",SUM(L42:L50)) -> 119
...

Sheet Consolidado Contratista
A1: Dotación Histórica AMSA — Consolidado Contratista por Vicepresidencia y Gerencia 2022–2026
A2: Dotación Contratista Actividad Corporativa · Promedio anual (N°) · Real vs Presupuesto · (Permanente + Temporal)
A4: Vicepresidencia / Gerencia | B4: 2022 | D4: 2023 | F4: 2024 | H4: 2025 | J4: 2026 YTD | L4: 2026 FY
B5: Real | C5: Ppto | D5: Real | E5: Ppto | F5: Real | G5: Ppto | H5: Real | I5: Ppto | J5: Real | K5: Ppto | L5: Ppto
A6: Auditoria | B6: =IF(COUNT(B7:B7)=0,"",SUM(B7:B7)) | C6: =IF(COUNT(C7:C7)=0,"",SUM(C7:C7)) | D6: =IF(COUNT(D7:D7)=0,"",SUM(D7:D7)) | E6: =IF(COUNT(E7:E7)=0,"",SUM(E7:E7)) | F6: =IF(COUNT(F7:F7)=0,"",SUM(F7:F7)) -> 0.25 | G6: =IF(COUNT(G7:G7)=0,"",SUM(G7:G7)) -> 1 | H6: =IF(COUNT(H7:H7)=0,"",SUM(H7:H7)) -> 2.25 | I6: =IF(COUNT(I7:I7)=0,"",SUM(I7:I7)) -> 1 | ... L6: =IF(COUNT(L7:L7)=0,"",SUM(L7:L7)) -> 1.5
A7: Auditoria | F7: =IFERROR(AVERAGE('2024'!G132:R132),"") -> 0.25 | G7: =IFERROR(AVERAGE('2024'!G133:R133),"") -> 1 | H7: =IFERROR(AVERAGE('2025'!G116:R116),"") -> 2.25 | I7: =IFERROR(AVERAGE('2025'!G117:R117),"") -> 1 | J7: =IFERROR(AVERAGE('2026'!G110:K110),"") -> 3 | K7: =IFERROR(AVERAGE('2026'!G111:K111),"") -> 1.8 | L7: =IFERROR(AVERAGE('2026'!G111:R111),"") -> 1.5
A8: Vicepresidencia de Asuntos Corporativos | B8: =IF(COUNT(B9:B10)=0,"",SUM(B9:B10)) | C8: =IF(COUNT(C9:C10)=0,"",SUM(C9:C10)) | D8: =IF(COUNT(D9:D10)=0,"",SUM(D9:D10)) | E8: =IF(COUNT(E9:E10)=0,"",SUM(E9:E10)) | F8: =IF(COUNT(F9:F10)=0,"",SUM(F9:F10)) | G8: =IF(COUNT(G9:G10)=0,"",SUM(G9:G10)) | H8: =IF(COUNT(H9:H10)=0,"",SUM(H9:H10)) -> 2 | I8: =IF(COUNT(I9:I10)=0,"",SUM(I9:I10)) -> 2 | ... L8: =IF(COUNT(L9:L10)=0,"",SUM(L9:L10)) -> 3
A9: Asuntos Públicos Corporativo | H9: =IFERROR(AVERAGE('2025'!G118:R118),"") -> 1 | I9: =IFERROR(AVERAGE('2025'!G119:R119),"") -> 1 | J9: =IFERROR(AVERAGE('2026'!G112:K112),"") -> 1.8 | K9: =IFERROR(AVERAGE('2026'!G113:K113),"") -> 2 | L9: =IFERROR(AVERAGE('2026'!G113:R113),"") -> 2
A10: Asuntos Publicos MLP | H10: =IFERROR(AVERAGE('2025'!G120:R120),"") -> 1 | I10: =IFERROR(AVERAGE('2025'!G121:R121),"") -> 1 | J10: =IFERROR(AVERAGE('2026'!G114:K114),"") -> 1 | K10: =IFERROR(AVERAGE('2026'!G115:K115),"") -> 1 | L10: =IFERROR(AVERAGE('2026'!G115:R115),"") -> 1
A11: Vicepresidencia de Proyectos | B11: =IF(COUNT(B12:B14)=0,"",SUM(B12:B14)) | C11: =IF(COUNT(C12:C14)=0,"",SUM(C12:C14)) | D11: =IF(COUNT(D12:D14)=0,"",SUM(D12:D14)) | E11: =IF(COUNT(E12:E14)=0,"",SUM(E12:E14)) | F11: =IF(COUNT(F12:F14)=0,"",SUM(F12:F14)) -> 21.054167 | G11: =IF(COUNT(G12:G14)=0,"",SUM(G12:G14)) -> 14 | H11: =IF(COUNT(H12:H14)=0,"",SUM(H12:H14)) -> 1.25 | I11: =IF(COUNT(I12:I14)=0,"",SUM(I12:I14)) -> 1 | ... L11: =IF(COUNT(L12:L14)=0,"",SUM(L12:L14)) -> 2
A12: Habilitadores CMZ | F12: =IFERROR(AVERAGE('2024'!G142:R142),0)+IFERROR(AVERAGE('2024'!G143:R143),0) -> 13.698333 | G12: =IFERROR(AVERAGE('2024'!G144:R144),"") -> 0
A13: Proyecto MLP Largo plazo | F13: =IFERROR(AVERAGE('2024'!G145:R145),"") -> 5.6891667 | G13: =IFERROR(AVERAGE('2024'!G146:R146),"") -> 12
A14: Vicepresidencia de Proyectos + Proyecto INCO + Proyecto Estudio | F14: =IFERROR(AVERAGE('2024'!G147:R147),0)+IFERROR(AVERAGE('2024'!G149:R149),0) -> 1.6666667 | G14: =IFERROR(AVERAGE('2024'!G148:R148),0)+IFERROR(AVERAGE('2024'!G150:R150),0) -> 2 | H14: =IFERROR(AVERAGE('2025'!G122:R122),"") -> 1.25 | I14: =IFERROR(AVERAGE('2025'!G123:R123),"") -> 1 | J14: =IFERROR(AVERAGE('2026'!G116:K116),"") -> 0.6 | K14: =IFERROR(AVERAGE('2026'!G117:K117),"") -> 2 | L14: =IFERROR(AVERAGE('2026'!G117:R117),"") -> 2
A15: Vicepresidencia Desarrollo | B15: =IF(COUNT(B16:B16)=0,"",SUM(B16:B16)) | C15: =IF(COUNT(C16:C16)=0,"",SUM(C16:C16)) | D15: =IF(COUNT(D16:D16)=0,"",SUM(D16:D16)) | E15: =IF(COUNT(E16:E16)=0,"",SUM(E16:E16)) | F15: =IF(COUNT(F16:F16)=0,"",SUM(F16:F16)) | G15: =IF(COUNT(G16:G16)=0,"",SUM(G16:G16)) | H15: =IF(COUNT(H16:H16)=0,"",SUM(H16:H16)) | I15: =IF(COUNT(I16:I16)=0,"",SUM(I16:I16)) | ... L15: =IF(COUNT(L16:L16)=0,"",SUM(L16:L16)) -> 4
A16: Vicepresidencia Desarrollo | J16: =IFERROR(AVERAGE('2026'!G118:K118),"") -> 4.6 | K16: =IFERROR(AVERAGE('2026'!G119:K119),"") -> 4 | L16: =IFERROR(AVERAGE('2026'!G119:R119),"") -> 4
A17: Vicepresidencia Estrategia e Innovación | B17: =IF(COUNT(B18:B21)=0,"",SUM(B18:B21)) -> 51.833333 | C17: =IF(COUNT(C18:C21)=0,"",SUM(C18:C21)) -> 52 | D17: =IF(COUNT(D18:D21)=0,"",SUM(D18:D21)) -> 24 | E17: =IF(COUNT(E18:E21)=0,"",SUM(E18:E21)) -> 24 | F17: =IF(COUNT(F18:F21)=0,"",SUM(F18:F21)) -> 26 | G17: =IF(COUNT(G18:G21)=0,"",SUM(G18:G21)) -> 26 | H17: =IF(COUNT(H18:H21)=0,"",SUM(H18:H21)) -> 24.833333 | I17: =IF(COUNT(I18:I21)=0,"",SUM(I18:I21)) -> 24 | ... L17: =IF(COUNT(L18:L21)=0,"",SUM(L18:L21)) -> 24
A18: Proyecto Descarbonización | H18: =IFERROR(AVERAGE('2025'!G124:R124),"") -> 0.66666667 | J18: =IFERROR(AVERAGE('2026'!G120:K120),"") -> 1 | K18: =IFERROR(AVERAGE('2026'!G121:K121),"") -> 1 | L18: =IFERROR(AVERAGE('2026'!G121:R121),"") -> 1
A19: Tecnologia | F19: =IFERROR(AVERAGE('2024'!G151:R151),"") -> 24 | G19: =IFERROR(AVERAGE('2024'!G152:R152),"") -> 24 | H19: =IFERROR(AVERAGE('2025'!G125:R125),"") -> 24 | I19: =IFERROR(AVERAGE('2025'!G126:R126),"") -> 24 | J19: =IFERROR(AVERAGE('2026'!G122:K122),"") -> 23.4 | K19: =IFERROR(AVERAGE('2026'!G123:K123),"") -> 23 | L19: =IFERROR(AVERAGE('2026'!G123:R123),"") -> 23
A20: TICA | B20: =IFERROR(AVERAGE('2022'!H112:S112),"") -> 51.833333 | C20: =IFERROR(AVERAGE('2022'!H113:S113),"") -> 52 | D20: =IFERROR(AVERAGE('2023'!G150:R150),0)+IFERROR(AVERAGE('2023'!G152:R152),0) -> 24 | E20: =IFERROR(AVERAGE('2023'!G151:R151),0)+IFERROR(AVERAGE('2023'!G153:R153),0) -> 24
A21: Vicepresidencia Estrategia e Innovación | F21: =IFERROR(AVERAGE('2024'!G153:R153),"") -> 2 | G21: =IFERROR(AVERAGE('2024'!G154:R154),"") -> 2 | H21: =IFERROR(AVERAGE('2025'!G127:R127),"") -> 0.16666667
A22: Vicepresidencia Finanzas | B22: =IF(COUNT(B23:B27)=0,"",SUM(B23:B27)) -> 13.166667 | C22: =IF(COUNT(C23:C27)=0,"",SUM(C23:C27)) -> 13.083333 | D22: =IF(COUNT(D23:D27)=0,"",SUM(D23:D27)) -> 72.25 | E22: =IF(COUNT(E23:E27)=0,"",SUM(E23:E27)) -> 71.75 | F22: =IF(COUNT(F23:F27)=0,"",SUM(F23:F27)) -> 22 | G22: =IF(COUNT(G23:G27)=0,"",SUM(G23:G27)) -> 27 | H22: =IF(COUNT(H23:H27)=0,"",SUM(H23:H27)) -> 7.5833333 | I22: =IF(COUNT(I23:I27)=0,"",SUM(I23:I27)) -> 22 | ... L22: =IF(COUNT(L23:L27)=0,"",SUM(L23:L27)) -> 10
A23: Abastecimiento | B23: =IFERROR(AVERAGE('2022'!H114:S114),"") -> 8.4166667 | C23: =IFERROR(AVERAGE('2022'!H115:S115),"") -> 8.0833333 | D23: =IFERROR(AVERAGE('2023'!G154:R154),0)+IFERROR(AVERAGE('2023'!G156:R156),0) -> 58.916667 | E23: =IFERROR(AVERAGE('2023'!G155:R155),0)+IFERROR(AVERAGE('2023'!G157:R157),0) -> 56 | F23: =IFERROR(AVERAGE('2024'!G155:R155),"") -> 15.833333 | G23: =IFERROR(AVERAGE('2024'!G156:R156),"") -> 17 | I23: =IFERROR(AVERAGE('2025'!G128:R128),"") -> 13
A24: Finanzas e Impuestos + Planificación Financiera | B24: =IFERROR(AVERAGE('2022'!H118:S118),"") -> 2.75 | C24: =IFERROR(AVERAGE('2022'!H119:S119),"") -> 3 | D24: =IFERROR(AVERAGE('2023'!G162:R162),0)+IFERROR(AVERAGE('2023'!G164:R164),0) -> 1.3333333 | E24: =IFERROR(AVERAGE('2023'!G163:R163),0)+IFERROR(AVERAGE('2023'!G165:R165),0) -> 3 | F24: =IFERROR(AVERAGE('2024'!G159:R159),"") -> 1.1666667 | G24: =IFERROR(AVERAGE('2024'!G160:R160),"") -> 3 | H24: =IFERROR(AVERAGE('2025'!G129:R129),"") -> 1.0833333 | I24: =IFERROR(AVERAGE('2025'!G130:R130),"") -> 3 | J24: =IFERROR(AVERAGE('2026'!G124:K124),"") -> 1 | K24: =IFERROR(AVERAGE('2026'!G125:K125),"") -> 3 | L24: =IFERROR(AVERAGE('2026'!G125:R125),"") -> 3
A25: Riesgo Compliance y Control Interno | D25: =IFERROR(AVERAGE('2023'!G166:R166),0)+IFERROR(AVERAGE('2023'!G168:R168),0) -> 1 | E25: =IFERROR(AVERAGE('2023'!G167:R167),0)+IFERROR(AVERAGE('2023'!G169:R169),0) -> 1 | F25: =IFERROR(AVERAGE('2024'!G161:R161),"") -> 3.8333333 | G25: =IFERROR(AVERAGE('2024'!G162:R162),"") -> 4 | H25: =IFERROR(AVERAGE('2025'!G131:R131),"") -> 5.0833333 | I25: =IFERROR(AVERAGE('2025'!G132:R132),"") -> 4 | J25: =IFERROR(AVERAGE('2026'!G126:K126),"") -> 4.2 | K25: =IFERROR(AVERAGE('2026'!G127:K127),"") -> 6 | L25: =IFERROR(AVERAGE('2026'!G127:R127),"") -> 6
A26: Contabilidad | B26: =IFERROR(AVERAGE('2022'!H116:S116),"") -> 2 | C26: =IFERROR(AVERAGE('2022'!H117:S117),"") -> 2 | D26: =IFERROR(AVERAGE('2023'!G158:R158),0)+IFERROR(AVERAGE('2023'!G160:R160),0) -> 11 | E26: =IFERROR(AVERAGE('2023'!G159:R159),0)+IFERROR(AVERAGE('2023'!G161:R161),0) -> 11.75 | F26: =IFERROR(AVERAGE('2024'!G157:R157),"") -> 0.083333333 | G26: =IFERROR(AVERAGE('2024'!G158:R158),"") -> 1
A27: Vicepresidencia Finanzas | F27: =IFERROR(AVERAGE('2024'!G163:R163),"") -> 1.0833333 | G27: =IFERROR(AVERAGE('2024'!G164:R164),"") -> 2 | H27: =IFERROR(AVERAGE('2025'!G133:R133),"") -> 1.4166667 | I27: =IFERROR(AVERAGE('2025'!G134:R134),"") -> 2 | J27: =IFERROR(AVERAGE('2026'!G128:K128),"") -> 1 | K27: =IFERROR(AVERAGE('2026'!G129:K129),"") -> 1 | L27: =IFERROR(AVERAGE('2026'!G129:R129),"") -> 1
A28: Vicepresidencia Legal | B28: =IF(COUNT(B29:B29)=0,"",SUM(B29:B29)) -> 3 | C28: =IF(COUNT(C29:C29)=0,"",SUM(C29:C29)) -> 3 | D28: =IF(COUNT(D29:D29)=0,"",SUM(D29:D29)) -> 3 | E28: =IF(COUNT(E29:E29)=0,"",SUM(E29:E29)) -> 3 | F28: =IF(COUNT(F29:F29)=0,"",SUM(F29:F29)) -> 3 | G28: =IF(COUNT(G29:G29)=0,"",SUM(G29:G29)) -> 3 | H28: =IF(COUNT(H29:H29)=0,"",SUM(H29:H29)) -> 2.3333333 | I28: =IF(COUNT(I29:I29)=0,"",SUM(I29:I29)) -> 3 | ... L28: =IF(COUNT(L29:L29)=0,"",SUM(L29:L29)) -> 3
A29: Propiedad Minera | B29: =IFERROR(AVERAGE('2022'!H120:S120),"") -> 3 | C29: =IFERROR(AVERAGE('2022'!H121:S121),"") -> 3 | D29: =IFERROR(AVERAGE('2023'!G170:R170),0)+IFERROR(AVERAGE('2023'!G172:R172),0) -> 3 | E29: =IFERROR(AVERAGE('2023'!G171:R171),0)+IFERROR(AVERAGE('2023'!G173:R173),0) -> 3 | F29: =IFERROR(AVERAGE('2024'!G165:R165),"") -> 3 | G29: =IFERROR(AVERAGE('2024'!G166:R166),"") -> 3 | H29: =IFERROR(AVERAGE('2025'!G135:R135),"") -> 2.3333333 | I29: =IFERROR(AVERAGE('2025'!G136:R136),"") -> 3 | J29: =IFERROR(AVERAGE('2026'!G130:K130),"") -> 2 | K29: =IFERROR(AVERAGE('2026'!G131:K131),"") -> 3 | L29: =IFERROR(AVERAGE('2026'!G131:R131),"") -> 3
A30: Vicepresidencia Personas y Organización | B30: =IF(COUNT(B31:B32)=0,"",SUM(B31:B32)) | C30: =IF(COUNT(C31:C32)=0,"",SUM(C31:C32)) | D30: =IF(COUNT(D31:D32)=0,"",SUM(D31:D32)) -> 12.5 | E30: =IF(COUNT(E31:E32)=0,"",SUM(E31:E32)) -> 14.583333 | F30: =IF(COUNT(F31:F32)=0,"",SUM(F31:F32)) -> 33.333333 | G30: =IF(COUNT(G31:G32)=0,"",SUM(G31:G32)) -> 34 | H30: =IF(COUNT(H31:H32)=0,"",SUM(H31:H32)) -> 34 | I30: =IF(COUNT(I31:I32)=0,"",SUM(I31:I32)) -> 34 | ... L30: =IF(COUNT(L31:L32)=0,"",SUM(L31:L32)) -> 35
A31: Desarrollo Organizacional y Compensaciones | F31: =IFERROR(AVERAGE('2024'!G167:R167),"") -> 33.333333 | G31: =IFERROR(AVERAGE('2024'!G168:R168),"") -> 34 | H31: =IFERROR(AVERAGE('2025'!G137:R137),"") -> 34 | I31: =IFERROR(AVERAGE('2025'!G138:R138),"") -> 34 | J31: =IFERROR(AVERAGE('2026'!G132:K132),"") -> 35 | K31: =IFERROR(AVERAGE('2026'!G133:K133),"") -> 35 | L31: =IFERROR(AVERAGE('2026'!G133:R133),"") -> 35
A32: Remuneraciones y Gestión de Recursos Humanos | D32: =IFERROR(AVERAGE('2023'!G174:R174),"") -> 12.5 | E32: =IFERROR(AVERAGE('2023'!G175:R175),"") -> 14.583333
A33: Vicepresidencia Sustentabilidad | B33: =IF(COUNT(B34:B35)=0,"",SUM(B34:B35)) | C33: =IF(COUNT(C34:C35)=0,"",SUM(C34:C35)) | D33: =IF(COUNT(D34:D35)=0,"",SUM(D34:D35)) | E33: =IF(COUNT(E34:E35)=0,"",SUM(E34:E35)) | F33: =IF(COUNT(F34:F35)=0,"",SUM(F34:F35)) | G33: =IF(COUNT(G34:G35)=0,"",SUM(G34:G35)) | H33: =IF(COUNT(H34:H35)=0,"",SUM(H34:H35)) -> 11.791667 | I33: =IF(COUNT(I34:I35)=0,"",SUM(I34:I35)) -> 14.083333 | ... L33: =IF(COUNT(L34:L35)=0,"",SUM(L34:L35)) -> 10
A34: Medio Ambiente | H34: =IFERROR(AVERAGE('2025'!G139:R139),"") -> 4.375 | I34: =IFERROR(AVERAGE('2025'!G140:R140),"") -> 6.0833333 | J34: =IFERROR(AVERAGE('2026'!G134:K134),"") -> 5 | K34: =IFERROR(AVERAGE('2026'!G135:K135),"") -> 5 | L34: =IFERROR(AVERAGE('2026'!G135:R135),"") -> 5
A35: Seguridad y Salud Ocupacional | H35: =IFERROR(AVERAGE('2025'!G141:R141),"") -> 7.4166667 | I35: =IFERROR(AVERAGE('2025'!G142:R142),"") -> 8 | J35: =IFERROR(AVERAGE('2026'!G136:K136),"") -> 6.2 | K35: =IFERROR(AVERAGE('2026'!G137:K137),"") -> 5 | L35: =IFERROR(AVERAGE('2026'!G137:R137),"") -> 5
A36: Vicepresidencia Asuntos Corporativos y Sustentabilidad | B36: =IF(COUNT(B37:B41)=0,"",SUM(B37:B41)) -> 14.49 | C36: =IF(COUNT(C37:C41)=0,"",SUM(C37:C41)) -> 14 | D36: =IF(COUNT(D37:D41)=0,"",SUM(D37:D41)) -> 16.284167 | E36: =IF(COUNT(E37:E41)=0,"",SUM(E37:E41)) -> 15 | F36: =IF(COUNT(F37:F41)=0,"",SUM(F37:F41)) -> 14.083333 | G36: =IF(COUNT(G37:G41)=0,"",SUM(G37:G41)) -> 11.25 | H36: =IF(COUNT(H37:H41)=0,"",SUM(H37:H41)) | I36: =IF(COUNT(I37:I41)=0,"",SUM(I37:I41)) | ... L36: =IF(COUNT(L37:L41)=0,"",SUM(L37:L41))
A37: Asuntos Públicos Corporativo | B37: =IFERROR(AVERAGE('2022'!H104:S104),"") -> 1 | C37: =IFERROR(AVERAGE('2022'!H105:S105),"") -> 1 | D37: =IFERROR(AVERAGE('2023'!G130:R130),0)+IFERROR(AVERAGE('2023'!G132:R132),0) -> 1.65 | E37: =IFERROR(AVERAGE('2023'!G131:R131),0)+IFERROR(AVERAGE('2023'!G133:R133),0) -> 2 | F37: =IFERROR(AVERAGE('2024'!G134:R134),"") -> 1 | G37: =IFERROR(AVERAGE('2024'!G135:R135),"") -> 1
A38: Asuntos Publicos MLP | D38: =IFERROR(AVERAGE('2023'!G134:R134),0)+IFERROR(AVERAGE('2023'!G136:R136),0) -> 0.83333333 | E38: =IFERROR(AVERAGE('2023'!G135:R135),0)+IFERROR(AVERAGE('2023'!G137:R137),0) -> 1 | F38: =IFERROR(AVERAGE('2024'!G136:R136),"") -> 1 | G38: =IFERROR(AVERAGE('2024'!G137:R137),"") -> 1
A39: Medio Ambiente | B39: =IFERROR(AVERAGE('2022'!H108:S108),"") -> 1.75 | C39: =IFERROR(AVERAGE('2022'!H109:S109),"") -> 3 | D39: =IFERROR(AVERAGE('2023'!G142:R142),0)+IFERROR(AVERAGE('2023'!G144:R144),0) -> 2.75 | E39: =IFERROR(AVERAGE('2023'!G143:R143),0)+IFERROR(AVERAGE('2023'!G145:R145),0) -> 3 | F39: =IFERROR(AVERAGE('2024'!G138:R138),"") -> 4.5833333 | G39: =IFERROR(AVERAGE('2024'!G139:R139),"") -> 3
A40: SSO | B40: =IFERROR(AVERAGE('2022'!H110:S110),"") -> 9.8333333 | C40: =IFERROR(AVERAGE('2022'!H111:S111),"") -> 9 | D40: =IFERROR(AVERAGE('2023'!G146:R146),0)+IFERROR(AVERAGE('2023'!G148:R148),0) -> 11.050833 | E40: =IFERROR(AVERAGE('2023'!G147:R147),0)+IFERROR(AVERAGE('2023'!G149:R149),0) -> 9 | F40: =IFERROR(AVERAGE('2024'!G140:R140),"") -> 7.5 | G40: =IFERROR(AVERAGE('2024'!G141:R141),"") -> 6.25
A41: Comunicaciones | B41: =IFERROR(AVERAGE('2022'!H106:S106),"") -> 1.9066667 | C41: =IFERROR(AVERAGE('2022'!H107:S107),"") -> 1 | D41: =IFERROR(AVERAGE('2023'!G138:R138),0)+IFERROR(AVERAGE('2023'!G140:R140),0) -> 0 | E41: =IFERROR(AVERAGE('2023'!G139:R139),0)+IFERROR(AVERAGE('2023'!G141:R141),0) -> 0
...

Sheet 2026
B1: Libro Dotación Minera AMSA
B3: Total Dotación Propia Actividad Corporativa | F3: Real | G3: 420 | H3: 419 | I3: 420 | J3: 415 | K3: 408 | L3: 0 | M3: 0 | N3: 0 | O3: 0 | P3: 0 | Q3: 0 | R3: 0 | U3: =+AVERAGE(G3:K3) -> 416.4
F4: Ppto | G4: 443 | H4: 443 | I4: 443 | J4: 443 | K4: 443 | L4: 443 | M4: 443 | N4: 443 | O4: 443 | P4: 443 | Q4: 443 | R4: 443 | U4: =+AVERAGE(G4:K4) -> 443
U5: =+AVERAGE(G5:K5) -> #DIV/0!
B6: Propia | F6: N° | G6: 202601 | H6: 202602 | I6: 202603 | J6: 202604 | K6: 202605 | L6: 202606 | M6: 202607 | N6: 202608 | O6: 202609 | P6: 202610 | Q6: 202611 | R6: 202612 | U6: =+AVERAGE(G6:K6) -> #DIV/0!
B7: Auditoria | D7: Auditoria | F7: Real | G7: 15 | H7: 15 | I7: 15 | J7: 15 | K7: 15 | L7: 0 | M7: 0 | N7: 0 | O7: 0 | P7: 0 | Q7: 0 | R7: 0 | U7: =+AVERAGE(G7:K7) -> 15
F8: Ppto | G8: 15 | H8: 15 | I8: 15 | J8: 15 | K8: 15 | L8: 15 | M8: 15 | N8: 15 | O8: 15 | P8: 15 | Q8: 15 | R8: 15 | U8: =+AVERAGE(G8:K8) -> 15
B9: Directorio | D9: Directorio | F9: Real | G9: 3 | H9: 3 | I9: 3 | J9: 3 | K9: 3 | L9: 0 | M9: 0 | N9: 0 | O9: 0 | P9: 0 | Q9: 0 | R9: 0 | U9: =+AVERAGE(G9:K9) -> 3
F10: Ppto | G10: 3 | H10: 3 | I10: 3 | J10: 3 | K10: 3 | L10: 3 | M10: 3 | N10: 3 | O10: 3 | P10: 3 | Q10: 3 | R10: 3 | U10: =+AVERAGE(G10:K10) -> 3
B11: Presidencia Ejecutiva | D11: Presidencia Ejecutiva | F11: Real | G11: 2 | H11: 2 | I11: 2 | J11: 2 | K11: 2 | L11: 0 | M11: 0 | N11: 0 | O11: 0 | P11: 0 | Q11: 0 | R11: 0 | U11: =+AVERAGE(G11:K11) -> 2
F12: Ppto | G12: 2 | H12: 2 | I12: 2 | J12: 2 | K12: 2 | L12: 2 | M12: 2 | N12: 2 | O12: 2 | P12: 2 | Q12: 2 | R12: 2 | U12: =+AVERAGE(G12:K12) -> 2
B13: Vicepresidencia ComercializaciÃ³n | D13: Ventas CÃ¡todos Molibdeno y Hedge | F13: Real | G13: 5 | H13: 5 | I13: 5 | J13: 5 | K13: 5 | L13: 0 | M13: 0 | N13: 0 | O13: 0 | P13: 0 | Q13: 0 | R13: 0 | U13: =+AVERAGE(G13:K13) -> 5
F14: Ppto | G14: 5 | H14: 5 | I14: 5 | J14: 5 | K14: 5 | L14: 5 | M14: 5 | N14: 5 | O14: 5 | P14: 5 | Q14: 5 | R14: 5 | U14: =+AVERAGE(G14:K14) -> 5
D15: Ventas Concentrado Acido | F15: Real | G15: 5 | H15: 5 | I15: 5 | J15: 5 | K15: 5 | L15: 0 | M15: 0 | N15: 0 | O15: 0 | P15: 0 | Q15: 0 | R15: 0 | U15: =+AVERAGE(G15:K15) -> 5
F16: Ppto | G16: 5 | H16: 5 | I16: 5 | J16: 5 | K16: 5 | L16: 5 | M16: 5 | N16: 5 | O16: 5 | P16: 5 | Q16: 5 | R16: 5 | U16: =+AVERAGE(G16:K16) -> 5
D17: Vicepresidencia ComercializaciÃ³n | F17: Real | G17: 9 | H17: 9 | I17: 9 | J17: 9 | K17: 9 | L17: 0 | M17: 0 | N17: 0 | O17: 0 | P17: 0 | Q17: 0 | R17: 0 | U17: =+AVERAGE(G17:K17) -> 9
F18: Ppto | G18: 9 | H18: 9 | I18: 9 | J18: 9 | K18: 9 | L18: 9 | M18: 9 | N18: 9 | O18: 9 | P18: 9 | Q18: 9 | R18: 9 | U18: =+AVERAGE(G18:K18) -> 9
D19: Asuntos Publicos MLP | F19: Real | G19: 19 | H19: 18 | I19: 18 | J19: 17 | K19: 15 | L19: 0 | M19: 0 | N19: 0 | O19: 0 | P19: 0 | Q19: 0 | R19: 0 | U19: =+AVERAGE(G19:K19) -> 17.4
F20: Ppto | G20: 18 | H20: 18 | I20: 18 | J20: 18 | K20: 18 | L20: 18 | M20: 18 | N20: 18 | O20: 18 | P20: 18 | Q20: 18 | R20: 18 | U20: =+AVERAGE(G20:K20) -> 18
D21: Asuntos PÃºblicos Norte | F21: Real | G21: 12 | H21: 14 | I21: 13 | J21: 13 | K21: 13 | L21: 0 | M21: 0 | N21: 0 | O21: 0 | P21: 0 | Q21: 0 | R21: 0 | U21: =+AVERAGE(G21:K21) -> 13
F22: Ppto | G22: 15 | H22: 15 | I22: 15 | J22: 15 | K22: 15 | L22: 15 | M22: 15 | N22: 15 | O22: 15 | P22: 15 | Q22: 15 | R22: 15 | U22: =+AVERAGE(G22:K22) -> 15
D23: Comunicaciones | F23: Real | G23: 7 | H23: 8 | I23: 8 | J23: 8 | K23: 8 | L23: 0 | M23: 0 | N23: 0 | O23: 0 | P23: 0 | Q23: 0 | R23: 0 | U23: =+AVERAGE(G23:K23) -> 7.8
F24: Ppto | G24: 8 | H24: 8 | I24: 8 | J24: 8 | K24: 8 | L24: 8 | M24: 8 | N24: 8 | O24: 8 | P24: 8 | Q24: 8 | R24: 8 | U24: =+AVERAGE(G24:K24) -> 8
D25: Vicepresidencia Asuntos Corporativos | F25: Real | G25: 10 | H25: 10 | I25: 10 | J25: 11 | K25: 11 | L25: 0 | M25: 0 | N25: 0 | O25: 0 | P25: 0 | Q25: 0 | R25: 0 | U25: =+AVERAGE(G25:K25) -> 10.4
F26: Ppto | G26: 11 | H26: 11 | I26: 11 | J26: 11 | K26: 11 | L26: 11 | M26: 11 | N26: 11 | O26: 11 | P26: 11 | Q26: 11 | R26: 11 | U26: =+AVERAGE(G26:K26) -> 11
B27: Vicepresidencia de Proyectos | D27: Finanzas VPP | F27: Real | G27: 14 | H27: 13 | I27: 13 | J27: 12 | K27: 13 | L27: 0 | M27: 0 | N27: 0 | O27: 0 | P27: 0 | Q27: 0 | R27: 0 | U27: =+AVERAGE(G27:K27) -> 13
F28: Ppto | G28: 14 | H28: 14 | I28: 14 | J28: 14 | K28: 14 | L28: 14 | M28: 14 | N28: 14 | O28: 14 | P28: 14 | Q28: 14 | R28: 14 | U28: =+AVERAGE(G28:K28) -> 14
D29: Ingenieria y Construccion | F29: Real | G29: 2 | H29: 2 | I29: 2 | J29: 2 | K29: 2 | L29: 0 | M29: 0 | N29: 0 | O29: 0 | P29: 0 | Q29: 0 | R29: 0 | U29: =+AVERAGE(G29:K29) -> 2
F30: Ppto | G30: 5 | H30: 5 | I30: 5 | J30: 5 | K30: 5 | L30: 5 | M30: 5 | N30: 5 | O30: 5 | P30: 5 | Q30: 5 | R30: 5 | U30: =+AVERAGE(G30:K30) -> 5
D31: Vicepresidencia de Proyectos + Proyecto INCO + Proyecto Estudio | F31: Real | G31: 10 | H31: 10 | I31: 10 | J31: 9 | K31: 8 | L31: 0 | M31: 0 | N31: 0 | O31: 0 | P31: 0 | Q31: 0 | R31: 0 | U31: =+AVERAGE(G31:K31) -> 9.4
F32: Ppto | G32: 8 | H32: 8 | I32: 8 | J32: 8 | K32: 8 | L32: 8 | M32: 8 | N32: 8 | O32: 8 | P32: 8 | Q32: 8 | R32: 8 | U32: =+AVERAGE(G32:K32) -> 8
B33: Vicepresidencia Desarrollo | D33: AdministraciÃ³n MIC | F33: Real | G33: 2 | H33: 2 | I33: 2 | J33: 2 | K33: 2 | L33: 0 | M33: 0 | N33: 0 | O33: 0 | P33: 0 | Q33: 0 | R33: 0 | U33: =+AVERAGE(G33:K33) -> 2
F34: Ppto | G34: 2 | H34: 2 | I34: 2 | J34: 2 | K34: 2 | L34: 2 | M34: 2 | N34: 2 | O34: 2 | P34: 2 | Q34: 2 | R34: 2 | U34: =+AVERAGE(G34:K34) -> 2
D35: Desarrollo | F35: Real | G35: 9 | H35: 9 | I35: 9 | J35: 8 | K35: 6 | L35: 0 | M35: 0 | N35: 0 | O35: 0 | P35: 0 | Q35: 0 | R35: 0 | U35: =+AVERAGE(G35:K35) -> 8.2
F36: Ppto | G36: 9 | H36: 9 | I36: 9 | J36: 9 | K36: 9 | L36: 9 | M36: 9 | N36: 9 | O36: 9 | P36: 9 | Q36: 9 | R36: 9 | U36: =+AVERAGE(G36:K36) -> 9
D37: Vicepresidencia Desarrollo | F37: Real | G37: 10 | H37: 9 | I37: 9 | J37: 8 | K37: 3 | L37: 0 | M37: 0 | N37: 0 | O37: 0 | P37: 0 | Q37: 0 | R37: 0 | U37: =+AVERAGE(G37:K37) -> 7.8
F38: Ppto | G38: 10 | H38: 10 | I38: 10 | J38: 10 | K38: 10 | L38: 10 | M38: 10 | N38: 10 | O38: 10 | P38: 10 | Q38: 10 | R38: 10 | U38: =+AVERAGE(G38:K38) -> 10
B39: Vicepresidencia Estrategia e InnovaciÃ³n | D39: Data y AnalÃ­tica Avanzada | F39: Real | G39: 8 | H39: 8 | I39: 8 | J39: 8 | K39: 9 | L39: 0 | M39: 0 | N39: 0 | O39: 0 | P39: 0 | Q39: 0 | R39: 0 | U39: =+AVERAGE(G39:K39) -> 8.2
F40: Ppto | G40: 8 | H40: 8 | I40: 8 | J40: 8 | K40: 8 | L40: 8 | M40: 8 | N40: 8 | O40: 8 | P40: 8 | Q40: 8 | R40: 8 | U40: =+AVERAGE(G40:K40) -> 8
D41: InnovaciÃ³n + EnergÃ­a y Recursos HÃ­dricos | F41: Real | G41: 5 | H41: 5 | I41: 5 | J41: 5 | K41: 4 | L41: 0 | M41: 0 | N41: 0 | O41: 0 | P41: 0 | Q41: 0 | R41: 0 | U41: =+AVERAGE(G41:K41) -> 4.8
...

Sheet 2025
B1: Libro Dotación Minera AMSA
B3: Total Dotación Propia Actividad Corporativa | F3: Real | G3: 421 | H3: 421 | I3: 417 | J3: 414 | K3: 415 | L3: 415 | M3: 417 | N3: 419 | O3: 417 | P3: 419 | Q3: 420 | R3: 420 | T3: =+R3 -> 420 | U3: =+AVERAGE(G3:R3) -> 417.91667 | V3: 421 | X3: 428 | Y3: 414 | Z3: 418 | AA3: 419 | AD3: 420 | AE3: 429
F4: Ppto | G4: 454 | H4: 454 | I4: 454 | J4: 457 | K4: 457 | L4: 457 | M4: 457 | N4: 457 | O4: 457 | P4: 457 | Q4: 457 | R4: 457 | T4: =+R4 -> 457 | U4: =+AVERAGE(G4:R4) -> 456.25 | V4: 457 | X4: 454 | Y4: 457 | Z4: 457 | AA4: 457 | AD4: 457 | AE4: 457
T5: =+R5 -> 0 | U5: =+AVERAGE(G5:R5) -> #DIV/0!
B6: Propia | F6: N° | G6: 202501 | H6: 202502 | I6: 202503 | J6: 202504 | K6: 202505 | L6: 202506 | M6: 202507 | N6: 202508 | O6: 202509 | P6: 202510 | Q6: 202511 | R6: 202512 | T6: =+R6 -> 202512 | U6: =+AVERAGE(G6:R6) -> #DIV/0! | V6: FY | X6: Q1 | Y6: Q2 | Z6: Q3 | AA6: Q4 | AD6: MES | AE6: YTD
B7: Auditoria | D7: Auditoria | F7: Real | G7: 13 | H7: 13 | I7: 14 | J7: 14 | K7: 14 | L7: 15 | M7: 15 | N7: 15 | O7: 15 | P7: 15 | Q7: 15 | R7: 15 | T7: =+R7 -> 15 | U7: =+AVERAGE(G7:R7) -> 14.416667 | V7: 14 | X7: 13 | Y7: 14 | Z7: 15 | AA7: 15 | AD7: 15 | AE7: 14
F8: Ppto | G8: 15 | H8: 15 | I8: 15 | J8: 15 | K8: 15 | L8: 15 | M8: 15 | N8: 15 | O8: 15 | P8: 15 | Q8: 15 | R8: 15 | T8: =+R8 -> 15 | U8: =+AVERAGE(G8:R8) -> 15 | V8: 15 | X8: 15 | Y8: 15 | Z8: 15 | AA8: 15 | AD8: 15 | AE8: 15
B9: Directorio | D9: Directorio | F9: Real | G9: 3 | H9: 3 | I9: 3 | J9: 3 | K9: 3 | L9: 3 | M9: 3 | N9: 3 | O9: 3 | P9: 3 | Q9: 3 | R9: 3 | T9: =+R9 -> 3 | U9: =+AVERAGE(G9:R9) -> 3 | V9: 3 | X9: 3 | Y9: 3 | Z9: 3 | AA9: 3 | AD9: 3 | AE9: 3
F10: Ppto | G10: 3 | H10: 3 | I10: 3 | J10: 3 | K10: 3 | L10: 3 | M10: 3 | N10: 3 | O10: 3 | P10: 3 | Q10: 3 | R10: 3 | T10: =+R10 -> 3 | U10: =+AVERAGE(G10:R10) -> 3 | V10: 3 | X10: 3 | Y10: 3 | Z10: 3 | AA10: 3 | AD10: 3 | AE10: 3
B11: Presidencia Ejecutiva | D11: Presidencia Ejecutiva | F11: Real | G11: 2 | H11: 2 | I11: 2 | J11: 2 | K11: 2 | L11: 2 | M11: 2 | N11: 2 | O11: 2 | P11: 2 | Q11: 2 | R11: 2 | T11: =+R11 -> 2 | U11: =+AVERAGE(G11:R11) -> 2 | V11: 2 | X11: 2 | Y11: 2 | Z11: 2 | AA11: 2 | AD11: 2 | AE11: 2
F12: Ppto | G12: 2 | H12: 2 | I12: 2 | J12: 2 | K12: 2 | L12: 2 | M12: 2 | N12: 2 | O12: 2 | P12: 2 | Q12: 2 | R12: 2 | T12: =+R12 -> 2 | U12: =+AVERAGE(G12:R12) -> 2 | V12: 2 | X12: 2 | Y12: 2 | Z12: 2 | AA12: 2 | AD12: 2 | AE12: 2
B13: Vicepresidencia Comercialización | D13: Ventas CÃ¡todos Molibdeno y Hedge | F13: Real | G13: 5 | H13: 5 | I13: 5 | J13: 5 | K13: 5 | L13: 5 | M13: 5 | N13: 5 | O13: 5 | P13: 5 | Q13: 5 | R13: 5 | T13: =+R13 -> 5 | U13: =+AVERAGE(G13:R13) -> 5 | V13: 5 | X13: 5 | Y13: 5 | Z13: 5 | AA13: 5 | AD13: 5 | AE13: 5
F14: Ppto | G14: 5 | H14: 5 | I14: 5 | J14: 5 | K14: 5 | L14: 5 | M14: 5 | N14: 5 | O14: 5 | P14: 5 | Q14: 5 | R14: 5 | T14: =+R14 -> 5 | U14: =+AVERAGE(G14:R14) -> 5 | V14: 5 | X14: 5 | Y14: 5 | Z14: 5 | AA14: 5 | AD14: 5 | AE14: 5
D15: Ventas Concentrado Acido | F15: Real | G15: 5 | H15: 5 | I15: 4 | J15: 5 | K15: 5 | L15: 5 | M15: 5 | N15: 5 | O15: 5 | P15: 5 | Q15: 5 | R15: 5 | T15: =+R15 -> 5 | U15: =+AVERAGE(G15:R15) -> 4.9166667 | V15: 5 | X15: 5 | Y15: 5 | Z15: 5 | AA15: 5 | AD15: 5 | AE15: 5
F16: Ppto | G16: 5 | H16: 5 | I16: 5 | J16: 5 | K16: 5 | L16: 5 | M16: 5 | N16: 5 | O16: 5 | P16: 5 | Q16: 5 | R16: 5 | T16: =+R16 -> 5 | U16: =+AVERAGE(G16:R16) -> 5 | V16: 5 | X16: 5 | Y16: 5 | Z16: 5 | AA16: 5 | AD16: 5 | AE16: 5
D17: Vicepresidencia ComercializaciÃ³n | F17: Real | G17: 8 | H17: 8 | I17: 9 | J17: 9 | K17: 9 | L17: 9 | M17: 9 | N17: 9 | O17: 9 | P17: 9 | Q17: 9 | R17: 9 | T17: =+R17 -> 9 | U17: =+AVERAGE(G17:R17) -> 8.8333333 | V17: 9 | X17: 8 | Y17: 9 | Z17: 9 | AA17: 9 | AD17: 9 | AE17: 9
F18: Ppto | G18: 10 | H18: 10 | I18: 10 | J18: 10 | K18: 10 | L18: 10 | M18: 10 | N18: 10 | O18: 10 | P18: 10 | Q18: 10 | R18: 10 | T18: =+R18 -> 10 | U18: =+AVERAGE(G18:R18) -> 10 | V18: 10 | X18: 10 | Y18: 10 | Z18: 10 | AA18: 10 | AD18: 10 | AE18: 10
B19: Vicepresidencia de Asuntos Corporativos | D19: Asuntos PÃºblicos Corporativo | F19: Real | G19: 3 | H19: 3 | I19: 3 | J19: 3 | K19: 3 | L19: 3 | M19: 3 | N19: 3 | O19: 2 | P19: 0 | Q19: 0 | R19: 0 | T19: =+R19 -> 0 | U19: =+AVERAGE(G19:R19) -> 2.1666667 | V19: 2 | X19: 3 | Y19: 3 | Z19: 3 | AA19: 0 | AD19: 0 | AE19: 3
F20: Ppto | G20: 5 | H20: 5 | I20: 5 | J20: 5 | K20: 5 | L20: 5 | M20: 5 | N20: 5 | O20: 5 | P20: 5 | Q20: 5 | R20: 5 | T20: =+R20 -> 5 | U20: =+AVERAGE(G20:R20) -> 5 | V20: 5 | X20: 5 | Y20: 5 | Z20: 5 | AA20: 5 | AD20: 5 | AE20: 5
D21: Asuntos PÃºblicos Norte | F21: Real | G21: 13 | H21: 13 | I21: 13 | J21: 13 | K21: 13 | L21: 13 | M21: 13 | N21: 12 | O21: 12 | P21: 11 | Q21: 11 | R21: 12 | T21: =+R21 -> 12 | U21: =+AVERAGE(G21:R21) -> 12.416667 | V21: 12 | X21: 13 | Y21: 13 | Z21: 12 | AA21: 11 | AD21: 12 | AE21: 12
F22: Ppto | G22: 13 | H22: 13 | I22: 13 | J22: 13 | K22: 13 | L22: 13 | M22: 13 | N22: 13 | O22: 13 | P22: 13 | Q22: 13 | R22: 13 | T22: =+R22 -> 13 | U22: =+AVERAGE(G22:R22) -> 13 | V22: 13 | X22: 13 | Y22: 13 | Z22: 13 | AA22: 13 | AD22: 13 | AE22: 13
D23: Asuntos Publicos MLP | F23: Real | G23: 19 | H23: 18 | I23: 17 | J23: 17 | K23: 19 | L23: 19 | M23: 19 | N23: 19 | O23: 19 | P23: 19 | Q23: 19 | R23: 19 | T23: =+R23 -> 19 | U23: =+AVERAGE(G23:R23) -> 18.583333 | V23: 19 | X23: 18 | Y23: 18 | Z23: 19 | AA23: 19 | AD23: 19 | AE23: 19
F24: Ppto | G24: 20 | H24: 20 | I24: 20 | J24: 20 | K24: 20 | L24: 20 | M24: 20 | N24: 20 | O24: 20 | P24: 20 | Q24: 20 | R24: 20 | T24: =+R24 -> 20 | U24: =+AVERAGE(G24:R24) -> 20 | V24: 20 | X24: 20 | Y24: 20 | Z24: 20 | AA24: 20 | AD24: 20 | AE24: 20
D25: Comunicaciones | F25: Real | G25: 8 | H25: 8 | I25: 8 | J25: 8 | K25: 8 | L25: 8 | M25: 8 | N25: 7 | O25: 7 | P25: 7 | Q25: 7 | R25: 7 | T25: =+R25 -> 7 | U25: =+AVERAGE(G25:R25) -> 7.5833333 | V25: 8 | X25: 8 | Y25: 8 | Z25: 7 | AA25: 7 | AD25: 7 | AE25: 8
F26: Ppto | G26: 8 | H26: 8 | I26: 8 | J26: 8 | K26: 8 | L26: 8 | M26: 8 | N26: 8 | O26: 8 | P26: 8 | Q26: 8 | R26: 8 | T26: =+R26 -> 8 | U26: =+AVERAGE(G26:R26) -> 8 | V26: 8 | X26: 8 | Y26: 8 | Z26: 8 | AA26: 8 | AD26: 8 | AE26: 8
D27: Vicepresidencia Asuntos Corporativos | F27: Real | G27: 3 | H27: 3 | I27: 4 | J27: 4 | K27: 4 | L27: 4 | M27: 4 | N27: 4 | O27: 4 | P27: 6 | Q27: 7 | R27: 7 | T27: =+R27 -> 7 | U27: =+AVERAGE(G27:R27) -> 4.5 | V27: 5 | X27: 3 | Y27: 4 | Z27: 4 | AA27: 7 | AD27: 7 | AE27: 5
F28: Ppto | G28: 3 | H28: 3 | I28: 3 | J28: 3 | K28: 3 | L28: 3 | M28: 3 | N28: 3 | O28: 3 | P28: 3 | Q28: 3 | R28: 3 | T28: =+R28 -> 3 | U28: =+AVERAGE(G28:R28) -> 3 | V28: 3 | X28: 3 | Y28: 3 | Z28: 3 | AA28: 3 | AD28: 3 | AE28: 3
B29: Vicepresidencia de Proyectos | D29: Finanzas VPP | F29: Real | G29: 11 | H29: 11 | I29: 11 | J29: 11 | K29: 12 | L29: 11 | M29: 11 | N29: 12 | O29: 13 | P29: 14 | Q29: 14 | R29: 15 | T29: =+R29 -> 15 | U29: =+AVERAGE(G29:R29) -> 12.166667 | V29: 12 | X29: 11 | Y29: 11 | Z29: 12 | AA29: 14 | AD29: 15 | AE29: 12
F30: Ppto | G30: 14 | H30: 14 | I30: 14 | J30: 14 | K30: 14 | L30: 14 | M30: 14 | N30: 14 | O30: 14 | P30: 14 | Q30: 14 | R30: 14 | T30: =+R30 -> 14 | U30: =+AVERAGE(G30:R30) -> 14 | V30: 14 | X30: 14 | Y30: 14 | Z30: 14 | AA30: 14 | AD30: 14 | AE30: 14
D31: Ingenieria y Construccion | F31: Real | G31: 3 | H31: 3 | I31: 2 | J31: 2 | K31: 2 | L31: 2 | M31: 2 | N31: 2 | O31: 2 | P31: 2 | Q31: 2 | R31: 2 | T31: =+R31 -> 2 | U31: =+AVERAGE(G31:R31) -> 2.1666667 | V31: 2 | X31: 3 | Y31: 2 | Z31: 2 | AA31: 2 | AD31: 2 | AE31: 2
F32: Ppto | G32: 5 | H32: 5 | I32: 5 | J32: 5 | K32: 5 | L32: 5 | M32: 5 | N32: 5 | O32: 5 | P32: 5 | Q32: 5 | R32: 5 | T32: =+R32 -> 5 | U32: =+AVERAGE(G32:R32) -> 5 | V32: 5 | X32: 5 | Y32: 5 | Z32: 5 | AA32: 5 | AD32: 5 | AE32: 5
D33: Vicepresidencia de Proyectos + Proyecto INCO + Proyecto Estudio | F33: Real | G33: 8 | H33: 8 | I33: 7 | J33: 7 | K33: 7 | L33: 9 | M33: 10 | N33: 11 | O33: 11 | P33: 11 | Q33: 12 | R33: 11 | T33: =+R33 -> 11 | U33: =+AVERAGE(G33:R33) -> 9.3333333 | V33: 9 | X33: 8 | Y33: 8 | Z33: 11 | AA33: 11 | AD33: 11 | AE33: 9
F34: Ppto | G34: 8 | H34: 8 | I34: 8 | J34: 8 | K34: 8 | L34: 8 | M34: 8 | N34: 8 | O34: 8 | P34: 8 | Q34: 8 | R34: 8 | T34: =+R34 -> 8 | U34: =+AVERAGE(G34:R34) -> 8 | V34: 8 | X34: 8 | Y34: 8 | Z34: 8 | AA34: 8 | AD34: 8 | AE34: 8
B35: Vicepresidencia Desarrollo | D35: AdministraciÃ³n MIC | F35: Real | G35: 2 | H35: 2 | I35: 2 | J35: 2 | K35: 2 | L35: 2 | M35: 2 | N35: 2 | O35: 2 | P35: 2 | Q35: 2 | R35: 2 | T35: =+R35 -> 2 | U35: =+AVERAGE(G35:R35) -> 2 | V35: 2 | X35: 2 | Y35: 2 | Z35: 2 | AA35: 2 | AD35: 2 | AE35: 2
F36: Ppto | G36: 3 | H36: 3 | I36: 3 | J36: 3 | K36: 3 | L36: 3 | M36: 3 | N36: 3 | O36: 3 | P36: 3 | Q36: 3 | R36: 3 | T36: =+R36 -> 3 | U36: =+AVERAGE(G36:R36) -> 3 | V36: 3 | X36: 3 | Y36: 3 | Z36: 3 | AA36: 3 | AD36: 3 | AE36: 3
D37: Desarrollo | F37: Real | G37: 9 | H37: 9 | I37: 9 | J37: 9 | K37: 9 | L37: 9 | M37: 9 | N37: 9 | O37: 9 | P37: 9 | Q37: 9 | R37: 9 | T37: =+R37 -> 9 | U37: =+AVERAGE(G37:R37) -> 9 | V37: 9 | X37: 9 | Y37: 9 | Z37: 9 | AA37: 9 | AD37: 9 | AE37: 9
F38: Ppto | G38: 9 | H38: 9 | I38: 9 | J38: 9 | K38: 9 | L38: 9 | M38: 9 | N38: 9 | O38: 9 | P38: 9 | Q38: 9 | R38: 9 | T38: =+R38 -> 9 | U38: =+AVERAGE(G38:R38) -> 9 | V38: 9 | X38: 9 | Y38: 9 | Z38: 9 | AA38: 9 | AD38: 9 | AE38: 9
D39: Vicepresidencia Desarrollo | F39: Real | G39: 11 | H39: 11 | I39: 11 | J39: 11 | K39: 10 | L39: 10 | M39: 10 | N39: 10 | O39: 10 | P39: 10 | Q39: 10 | R39: 10 | T39: =+R39 -> 10 | U39: =+AVERAGE(G39:R39) -> 10.333333 | V39: 10 | X39: 11 | Y39: 10 | Z39: 10 | AA39: 10 | AD39: 10 | AE39: 10
F40: Ppto | G40: 10 | H40: 10 | I40: 10 | J40: 10 | K40: 10 | L40: 10 | M40: 10 | N40: 10 | O40: 10 | P40: 10 | Q40: 10 | R40: 10 | T40: =+R40 -> 10 | U40: =+AVERAGE(G40:R40) -> 10 | V40: 10 | X40: 10 | Y40: 10 | Z40: 10 | AA40: 10 | AD40: 10 | AE40: 10
B41: Vicepresidencia Estrategia e InnovaciÃ³n | D41: Data y AnalÃ­tica Avanzada | F41: Real | G41: 8 | H41: 8 | I41: 8 | J41: 8 | K41: 8 | L41: 8 | M41: 8 | N41: 8 | O41: 8 | P41: 8 | Q41: 8 | R41: 8 | T41: =+R41 -> 8 | U41: =+AVERAGE(G41:R41) -> 8 | V41: 8 | X41: 8 | Y41: 8 | Z41: 8 | AA41: 8 | AD41: 8 | AE41: 8
...

Sheet 2024
B1: Libro Dotación Minera AMSA
B3: Total Dotación Propia Actividad Corporativa | F3: Real | G3: 398 | H3: 401 | I3: 404 | J3: 414 | K3: 416 | L3: 422 | M3: 429 | N3: 429 | O3: 426 | P3: 423 | Q3: 424 | R3: 426 | T3: 426 | U3: =+AVERAGE(G3:R3) -> 417.66667 | V3: 448 | X3: 406 | Y3: 417 | Z3: 493 | AA3: 425 | AC3: 426 | AD3: 488
F4: Ppto | G4: 428 | H4: 428 | I4: 429 | J4: 432 | K4: 432 | L4: 432 | M4: 432 | N4: 432 | O4: 431 | P4: 430 | Q4: 430 | R4: 430 | T4: 430 | U4: =+AVERAGE(G4:R4) -> 430.5 | V4: 431 | X4: 428 | Y4: 432 | Z4: 432 | AA4: 430 | AC4: 430 | AD4: 431
B6: Propia | F6: N° | G6: 202401 | H6: 202402 | I6: 202403 | J6: 202404 | K6: 202405 | L6: 202406 | M6: 202407 | N6: 202408 | O6: 202409 | P6: 202410 | Q6: 202411 | R6: 202412 | T6: MES | U6: YTD | V6: FY | X6: Q1 | Y6: Q2 | Z6: Q3 | AA6: Q4 | AC6: MES | AD6: YTD
B7: Auditoria | D7: Auditoria | F7: Real | G7: 11 | H7: 12 | I7: 14 | J7: 14 | K7: 14 | L7: 14 | M7: 14 | N7: 14 | O7: 14 | P7: 14 | Q7: 13 | R7: 13 | T7: 13 | U7: 13 | V7: 13 | X7: 12 | Y7: 14 | Z7: 14 | AA7: 13 | AC7: 13 | AD7: 13
F8: Ppto | G8: 14 | H8: 14 | I8: 14 | J8: 14 | K8: 14 | L8: 14 | M8: 14 | N8: 14 | O8: 14 | P8: 14 | Q8: 14 | R8: 14 | T8: 14 | U8: 14 | V8: 14 | X8: 14 | Y8: 14 | Z8: 14 | AA8: 14 | AC8: 14 | AD8: 14
B9: Directorio | D9: Directorio | F9: Real | G9: 3 | H9: 3 | I9: 3 | J9: 3 | K9: 3 | L9: 3 | M9: 3 | N9: 3 | O9: 3 | P9: 3 | Q9: 3 | R9: 3 | T9: 3 | U9: 3 | V9: 3 | X9: 3 | Y9: 3 | Z9: 3 | AA9: 3 | AC9: 3 | AD9: 3
F10: Ppto | G10: 3 | H10: 3 | I10: 3 | J10: 3 | K10: 3 | L10: 3 | M10: 3 | N10: 3 | O10: 3 | P10: 3 | Q10: 3 | R10: 3 | T10: 3 | U10: 3 | V10: 3 | X10: 3 | Y10: 3 | Z10: 3 | AA10: 3 | AC10: 3 | AD10: 3
B11: Presidencia Ejecutiva | D11: Presidencia Ejecutiva | F11: Real | G11: 2 | H11: 2 | I11: 2 | J11: 2 | K11: 2 | L11: 2 | M11: 2 | N11: 2 | O11: 2 | P11: 2 | Q11: 2 | R11: 2 | T11: 2 | U11: 2 | V11: 2 | X11: 2 | Y11: 2 | Z11: 2 | AA11: 2 | AC11: 2 | AD11: 2
F12: Ppto | G12: 2 | H12: 2 | I12: 2 | J12: 2 | K12: 2 | L12: 2 | M12: 2 | N12: 2 | O12: 2 | P12: 2 | Q12: 2 | R12: 2 | T12: 2 | U12: 2 | V12: 2 | X12: 2 | Y12: 2 | Z12: 2 | AA12: 2 | AC12: 2 | AD12: 2
B13: Vicepresidencia Asuntos Corporativos y Sustentabilidad | D13: Asuntos Públicos Corporativo | F13: Real | G13: 5 | H13: 5 | I13: 5 | J13: 5 | K13: 5 | L13: 4 | M13: 4 | N13: 0 | O13: 0 | P13: 0 | Q13: 0 | R13: 0 | T13: 0 | U13: 5 | V13: 3 | X13: 5 | Y13: 5 | Z13: 4 | AA13: 0 | AC13: 0 | AD13: 5
F14: Ppto | G14: 14 | H14: 14 | I14: 14 | J14: 14 | K14: 14 | L14: 14 | M14: 14 | N14: 14 | O14: 14 | P14: 14 | Q14: 14 | R14: 14 | T14: 14 | U14: 14 | V14: 14 | X14: 14 | Y14: 14 | Z14: 14 | AA14: 14 | AC14: 14 | AD14: 14
D15: Asuntos Publicos MLP | F15: Real | G15: 17 | H15: 17 | I15: 18 | J15: 18 | K15: 18 | L15: 18 | M15: 18 | N15: 0 | O15: 0 | P15: 0 | Q15: 0 | R15: 0 | T15: 0 | U15: 18 | V15: 10 | X15: 17 | Y15: 18 | Z15: 18 | AA15: 0 | AC15: 0 | AD15: 18
F16: Ppto | G16: 20 | H16: 20 | I16: 20 | J16: 20 | K16: 20 | L16: 20 | M16: 20 | N16: 20 | O16: 20 | P16: 20 | Q16: 20 | R16: 20 | T16: 20 | U16: 20 | V16: 20 | X16: 20 | Y16: 20 | Z16: 20 | AA16: 20 | AC16: 20 | AD16: 20
D17: Asuntos Públicos Norte | F17: Real | G17: 12 | H17: 13 | I17: 12 | J17: 13 | K17: 13 | L17: 13 | M17: 13 | N17: 0 | O17: 0 | P17: 0 | Q17: 0 | R17: 0 | T17: 0 | U17: 13 | V17: 7 | X17: 12 | Y17: 13 | Z17: 13 | AA17: 0 | AC17: 0 | AD17: 13
F18: Ppto | G18: 8 | H18: 8 | I18: 8 | J18: 8 | K18: 8 | L18: 8 | M18: 8 | N18: 8 | O18: 8 | P18: 8 | Q18: 8 | R18: 8 | T18: 8 | U18: 8 | V18: 8 | X18: 8 | Y18: 8 | Z18: 8 | AA18: 8 | AC18: 8 | AD18: 8
D19: Comunicaciones | F19: Real | G19: 8 | H19: 8 | I19: 8 | J19: 8 | K19: 8 | L19: 8 | M19: 8 | N19: 0 | O19: 0 | P19: 0 | Q19: 0 | R19: 0 | T19: 0 | U19: 8 | V19: 5 | X19: 8 | Y19: 8 | Z19: 8 | AA19: 0 | AC19: 0 | AD19: 8
F20: Ppto | G20: 8 | H20: 8 | I20: 8 | J20: 8 | K20: 8 | L20: 8 | M20: 8 | N20: 8 | O20: 8 | P20: 8 | Q20: 8 | R20: 8 | T20: 8 | U20: 8 | V20: 8 | X20: 8 | Y20: 8 | Z20: 8 | AA20: 8 | AC20: 8 | AD20: 8
D21: Medio Ambiente | F21: Real | G21: 7 | H21: 7 | I21: 7 | J21: 7 | K21: 7 | L21: 7 | M21: 7 | N21: 0 | O21: 0 | P21: 0 | Q21: 0 | R21: 0 | T21: 0 | U21: 7 | V21: 4 | X21: 7 | Y21: 7 | Z21: 7 | AA21: 0 | AC21: 0 | AD21: 7
F22: Ppto | G22: 7 | H22: 7 | I22: 7 | J22: 7 | K22: 7 | L22: 7 | M22: 7 | N22: 7 | O22: 7 | P22: 7 | Q22: 7 | R22: 7 | T22: 7 | U22: 7 | V22: 7 | X22: 7 | Y22: 7 | Z22: 7 | AA22: 7 | AC22: 7 | AD22: 7
D23: SSO | F23: Real | G23: 4 | H23: 4 | I23: 4 | J23: 4 | K23: 4 | L23: 4 | M23: 4 | N23: 0 | O23: 0 | P23: 0 | Q23: 0 | R23: 0 | T23: 0 | U23: 4 | V23: 2 | X23: 4 | Y23: 4 | Z23: 4 | AA23: 0 | AC23: 0 | AD23: 4
F24: Ppto | G24: 4 | H24: 4 | I24: 4 | J24: 4 | K24: 4 | L24: 4 | M24: 4 | N24: 4 | O24: 4 | P24: 4 | Q24: 4 | R24: 4 | T24: 4 | U24: 4 | V24: 4 | X24: 4 | Y24: 4 | Z24: 4 | AA24: 4 | AC24: 4 | AD24: 4
D25: Vicepresidencia Asuntos Corporativos y Sustentabilidad | F25: Real | G25: 7 | H25: 7 | I25: 7 | J25: 7 | K25: 7 | L25: 7 | M25: 7 | N25: 0 | O25: 0 | P25: 0 | Q25: 0 | R25: 0 | T25: 0 | U25: 7 | V25: 4 | X25: 7 | Y25: 7 | Z25: 7 | AA25: 0 | AC25: 0 | AD25: 7
F26: Ppto | G26: 6 | H26: 6 | I26: 6 | J26: 7 | K26: 7 | L26: 7 | M26: 7 | N26: 7 | O26: 7 | P26: 7 | Q26: 7 | R26: 7 | T26: 7 | U26: 7 | V26: 7 | X26: 6 | Y26: 7 | Z26: 7 | AA26: 7 | AC26: 7 | AD26: 7
B27: Vicepresidencia Comercialización | D27: Ventas Cátodos Molibdeno y Hedge | F27: Real | G27: 4 | H27: 4 | I27: 5 | J27: 5 | K27: 5 | L27: 5 | M27: 5 | N27: 5 | O27: 5 | P27: 5 | Q27: 5 | R27: 5 | T27: 5 | U27: 5 | V27: 5 | X27: 4 | Y27: 5 | Z27: 5 | AA27: 5 | AC27: 5 | AD27: 5
F28: Ppto | G28: 5 | H28: 5 | I28: 5 | J28: 6 | K28: 6 | L28: 6 | M28: 6 | N28: 6 | O28: 6 | P28: 6 | Q28: 6 | R28: 6 | T28: 6 | U28: 6 | V28: 6 | X28: 5 | Y28: 6 | Z28: 6 | AA28: 6 | AC28: 6 | AD28: 6
D29: Ventas Concentrado Acido | F29: Real | G29: 4 | H29: 4 | I29: 4 | J29: 4 | K29: 5 | L29: 5 | M29: 5 | N29: 5 | O29: 5 | P29: 5 | Q29: 5 | R29: 5 | T29: 5 | U29: 5 | V29: 5 | X29: 4 | Y29: 5 | Z29: 5 | AA29: 5 | AC29: 5 | AD29: 5
F30: Ppto | G30: 4 | H30: 4 | I30: 4 | J30: 4 | K30: 4 | L30: 4 | M30: 4 | N30: 4 | O30: 4 | P30: 4 | Q30: 4 | R30: 4 | T30: 4 | U30: 4 | V30: 4 | X30: 4 | Y30: 4 | Z30: 4 | AA30: 4 | AC30: 4 | AD30: 4
D31: Vicepresidencia Comercialización | F31: Real | G31: 10 | H31: 10 | I31: 10 | J31: 10 | K31: 9 | L31: 9 | M31: 9 | N31: 9 | O31: 9 | P31: 9 | Q31: 9 | R31: 9 | T31: 9 | U31: 9 | V31: 9 | X31: 10 | Y31: 9 | Z31: 9 | AA31: 9 | AC31: 9 | AD31: 9
F32: Ppto | G32: 10 | H32: 10 | I32: 10 | J32: 10 | K32: 10 | L32: 10 | M32: 10 | N32: 10 | O32: 10 | P32: 10 | Q32: 10 | R32: 10 | T32: 10 | U32: 10 | V32: 10 | X32: 10 | Y32: 10 | Z32: 10 | AA32: 10 | AC32: 10 | AD32: 10
B33: Vicepresidencia de Asuntos Corporativos | D33: Asuntos Públicos Corporativo | F33: Real | G33: 0 | H33: 0 | I33: 0 | J33: 0 | K33: 0 | L33: 0 | M33: 0 | N33: 4 | O33: 4 | P33: 4 | Q33: 4 | R33: 4 | T33: 4 | U33: 4 | V33: 3 | X33: 0 | Y33: 0 | Z33: 4 | AA33: 4 | AC33: 4 | AD33: 4
F34: Ppto | G34: 0 | H34: 0 | I34: 0 | J34: 0 | K34: 0 | L34: 0 | M34: 0 | N34: 0 | O34: 0 | P34: 0 | Q34: 0 | R34: 0 | T34: 0 | U34: 0 | V34: 0 | X34: 0 | Y34: 0 | Z34: 0 | AA34: 0 | AC34: 0 | AD34: 0
D35: Asuntos Publicos MLP | F35: Real | G35: 0 | H35: 0 | I35: 0 | J35: 0 | K35: 0 | L35: 0 | M35: 0 | N35: 19 | O35: 19 | P35: 19 | Q35: 20 | R35: 20 | T35: 20 | U35: 19 | V35: 16 | X35: 0 | Y35: 0 | Z35: 19 | AA35: 20 | AC35: 20 | AD35: 19
F36: Ppto | G36: 0 | H36: 0 | I36: 0 | J36: 0 | K36: 0 | L36: 0 | M36: 0 | N36: 0 | O36: 0 | P36: 0 | Q36: 0 | R36: 0 | T36: 0 | U36: 0 | V36: 0 | X36: 0 | Y36: 0 | Z36: 0 | AA36: 0 | AC36: 0 | AD36: 0
D37: Asuntos Públicos Norte | F37: Real | G37: 0 | H37: 0 | I37: 0 | J37: 0 | K37: 0 | L37: 0 | M37: 0 | N37: 14 | O37: 14 | P37: 13 | Q37: 13 | R37: 13 | T37: 13 | U37: 13 | V37: 11 | X37: 0 | Y37: 0 | Z37: 14 | AA37: 13 | AC37: 13 | AD37: 13
F38: Ppto | G38: 0 | H38: 0 | I38: 0 | J38: 0 | K38: 0 | L38: 0 | M38: 0 | N38: 0 | O38: 0 | P38: 0 | Q38: 0 | R38: 0 | T38: 0 | U38: 0 | V38: 0 | X38: 0 | Y38: 0 | Z38: 0 | AA38: 0 | AC38: 0 | AD38: 0
D39: Comunicaciones | F39: Real | G39: 0 | H39: 0 | I39: 0 | J39: 0 | K39: 0 | L39: 0 | M39: 0 | N39: 8 | O39: 8 | P39: 8 | Q39: 8 | R39: 8 | T39: 8 | U39: 8 | V39: 7 | X39: 0 | Y39: 0 | Z39: 8 | AA39: 8 | AC39: 8 | AD39: 8
F40: Ppto | G40: 0 | H40: 0 | I40: 0 | J40: 0 | K40: 0 | L40: 0 | M40: 0 | N40: 0 | O40: 0 | P40: 0 | Q40: 0 | R40: 0 | T40: 0 | U40: 0 | V40: 0 | X40: 0 | Y40: 0 | Z40: 0 | AA40: 0 | AC40: 0 | AD40: 0
D41: Vicepresidencia Asuntos Corporativos | F41: Real | G41: 0 | H41: 0 | I41: 0 | J41: 0 | K41: 0 | L41: 0 | M41: 0 | N41: 2 | O41: 2 | P41: 2 | Q41: 3 | R41: 3 | T41: 3 | U41: 2 | V41: 2 | X41: 0 | Y41: 0 | Z41: 2 | AA41: 3 | AC41: 3 | AD41: 2
F42: Ppto | G42: 0 | H42: 0 | I42: 0 | J42: 0 | K42: 0 | L42: 0 | M42: 0 | N42: 0 | O42: 0 | P42: 0 | Q42: 0 | R42: 0 | T42: 0 | U42: 0 | V42: 0 | X42: 0 | Y42: 0 | Z42: 0 | AA42: 0 | AC42: 0 | AD42: 0
...

Sheet 2023
G1: 646 | H1: 646 | I1: 631 | J1: 628 | K1: 630 | L1: 639 | M1: 644 | N1: 648 | O1: 649 | P1: 662 | Q1: 665 | R1: 675 | S1: 646.91667
G2: 737 | H2: 751 | I2: 741 | J2: 728 | K2: 735 | L2: 734 | M2: 730 | N2: 731 | O2: 732 | P2: 736 | Q2: 746 | R2: 746 | S2: 737.25
B3: Total Dotación Propia Actividad Corporativa | F3: Real | G3: 387 | H3: 387 | I3: 387 | J3: 385 | K3: 386 | L3: 393 | M3: 391 | N3: 394 | O3: 397 | P3: 397 | Q3: 393 | R3: 398 | S3: 391.25 | T3: 398 | U3: 459 | V3: 448 | X3: 389 | Y3: 392 | Z3: 429 | AA3: 396
F4: Ppto | G4: 420 | H4: 420 | I4: 420 | J4: 415 | K4: 415 | L4: 415 | M4: 414 | N4: 414 | O4: 414 | P4: 414 | Q4: 414 | R4: 414 | S4: 415.75 | T4: 414 | U4: 456 | V4: 456 | X4: 420 | Y4: 415 | Z4: 455 | AA4: 414
S5: #DIV/0!
B6: Propia | F6: N° | G6: 202301 | H6: 202302 | I6: 202303 | J6: 202304 | K6: 202305 | L6: 202306 | M6: 202307 | N6: 202308 | O6: 202309 | P6: 202310 | Q6: 202311 | R6: 202312 | S6: #DIV/0! | T6: MES | U6: YTD | V6: FY | X6: Q1 | Y6: Q2 | Z6: Q3 | AA6: Q4
B7: Auditoria | D7: Auditoria | F7: Real | G7: 12 | H7: 12 | I7: 12 | J7: 12 | K7: 12 | L7: 12 | M7: 12 | N7: 11 | O7: 11 | P7: 11 | Q7: 11 | R7: 10 | S7: 11.5 | T7: 10 | U7: 12 | V7: 12 | X7: 12 | Y7: 12 | Z7: 11 | AA7: 11
F8: Ppto | G8: 12 | H8: 12 | I8: 12 | J8: 12 | K8: 12 | L8: 12 | M8: 12 | N8: 12 | O8: 12 | P8: 12 | Q8: 12 | R8: 12 | S8: 12 | T8: 12 | U8: 12 | V8: 12 | X8: 12 | Y8: 12 | Z8: 12 | AA8: 12
B9: Directorio | D9: Directorio | F9: Real | G9: 3 | H9: 3 | I9: 3 | J9: 3 | K9: 3 | L9: 3 | M9: 3 | N9: 3 | O9: 3 | P9: 3 | Q9: 3 | R9: 3 | S9: 3 | T9: 3 | U9: 3 | V9: 3 | X9: 3 | Y9: 3 | Z9: 3 | AA9: 3
F10: Ppto | G10: 3 | H10: 3 | I10: 3 | J10: 3 | K10: 3 | L10: 3 | M10: 3 | N10: 3 | O10: 3 | P10: 3 | Q10: 3 | R10: 3 | S10: 3 | T10: 3 | U10: 3 | V10: 3 | X10: 3 | Y10: 3 | Z10: 3 | AA10: 3
B11: Presidencia Ejecutiva | D11: Presidencia Ejecutiva | F11: Real | G11: 2 | H11: 2 | I11: 2 | J11: 2 | K11: 2 | L11: 2 | M11: 2 | N11: 2 | O11: 2 | P11: 2 | Q11: 2 | R11: 2 | S11: 2 | T11: 2 | U11: 2 | V11: 2 | X11: 2 | Y11: 2 | Z11: 2 | AA11: 2
